Workbook

Sheet ■입주정보
B1: 건물명 | C1: 호실 | D1: 입주자 | E1: 코드 | F1: 납부기한 | G1: 전월 청구 | H1: 전월 청구 | I1: 당월청구 | J1: 당월청구 | K1: 연체료 | L1: 입주일 | M1: 만기일 | N1: 주민번호(사업자번호) | O1: 연락처 | P1: 예치금 | Q1: 임대료 | S1: 관리비 | U1: 수도 | W1: 케이블 | Y1: 기타 보증금 | AA1: 차량 번호 | AB1: 청소비 | AC1: 중개수수료 | AE1: 부동산 | AF1: 부동산 | AG1: 전입신고 | AH1: 애완동물 | AI1: 기타 | AJ1: 세입자 연결 | AK1: 호실 유형 | AL1: 재계약일 | AM1: 납부일
G2: 건물주 | H2: 하우스맨 | I2: 건물주 | J2: 하우스맨 | Q2: 금액 | R2: 선/후불 | S2: 금액 | T2: 선/후불 | U2: 금액 | V2: 선/후불 | W2: 금액 | X2: 선/후불 | Y2: 금액 | Z2: 유형 | AC2: 기본 | AD2: 추가(이벤트) | AF2: 연락처 | AH2: (날짜 기입)
B3: =COLUMN()-1 -> 1 | C3: =COLUMN()-1 -> 2 | D3: =COLUMN()-1 -> 3 | E3: =COLUMN()-1 -> 4 | F3: =COLUMN()-1 -> 5 | G3: =COLUMN()-1 -> 6 | H3: =COLUMN()-1 -> 7 | I3: =COLUMN()-1 -> 8 | ... AC3: =COLUMN()-1 -> 28 | AE3: =COLUMN()-1 -> 30 | AF3: =COLUMN()-1 -> 31 | AG3: =COLUMN()-1 -> 32 | AH3: =COLUMN()-1 -> 33 | AI3: =COLUMN()-1 -> 34 | AJ3: =COLUMN()-1 -> 35 | AK3: =COLUMN()-1 -> 36 | AL3: =COLUMN()-1 -> 37 | AM3: =COLUMN()-1 -> 38
B4: =_xlfn.LET(_xlpm.var,◆관리정보!B4,IF(_xlpm.var<>0,_xlpm.var,"")) -> 제이앤제이 | C4: =_xlfn.LET(_xlpm.var,◆관리정보!C4,IF(_xlpm.var<>0,_xlpm.var,"")) -> B01 | D4: 윤슬기 | E4: =_xlfn.CONCAT(B4,C4) -> 제이앤제이B01 | F4: 46117 | I4: =852640-160000-400000-50000-100000-100000-60000 -> -17360 | L4: 45721 | M4: 45812 | N4: 990908-2105818 | O4: 010-2378-5747 | P4: 650000 | Q4: 650000 | S4: 70000 | T4: 선불 | U4: 25000 | V4: 선불 | W4: 25000 | X4: 선불 | AB4: 100000 | AC4: 100000 | AE4: 리안부동산 | AF4: 010-2640-9065 | AL4: {=_xlfn.IFS( AND($AK4<>"", M4<>0, M4<=EDATE(TODAY(),2)),"도래", AND($AK4<>"", M4<>0, M4<=EDATE(TODAY(),3)),"예정", AND($AK4<>"", M4<>0, M4<=EDATE(TODAY(),6)),"관심", TRUE,"" )} | AM4: =DAY(L4) -> 5
B5: =_xlfn.LET(_xlpm.var,◆관리정보!B5,IF(_xlpm.var<>0,_xlpm.var,"")) -> 제이앤제이 | C5: =_xlfn.LET(_xlpm.var,◆관리정보!C5,IF(_xlpm.var<>0,_xlpm.var,"")) -> 101 | D5: 김용수 | E5: =_xlfn.CONCAT(B5,C5) -> 제이앤제이101 | F5: 46113 | L5: 45748 | M5: 46477 | N5: 791101-1052311 | O5: 010-3202-1081 | P5: 10000000 | Q5: 1150000 | AI5: 첫달(4/1~4/30) 임대료 무료 / 청소 조건으로 관리비 면제 | AK5: 상가/사무실 | AL5: {=_xlfn.IFS( AND($AK5<>"", M5<>0, M5<=EDATE(TODAY(),2)),"도래", AND($AK5<>"", M5<>0, M5<=EDATE(TODAY(),3)),"예정", AND($AK5<>"", M5<>0, M5<=EDATE(TODAY(),6)),"관심", TRUE,"" )} | AM5: =DAY(L5) -> 1
B6: =_xlfn.LET(_xlpm.var,◆관리정보!B6,IF(_xlpm.var<>0,_xlpm.var,"")) -> 제이앤제이 | C6: =_xlfn.LET(_xlpm.var,◆관리정보!C6,IF(_xlpm.var<>0,_xlpm.var,"")) -> 201 | D6: 박정미 | E6: =_xlfn.CONCAT(B6,C6) -> 제이앤제이201 | F6: 46115 | L6: 43162 | M6: 43345 | N6: 641101-2454626 | O6: 010-8720-2709 | P6: 1400000 | Q6: 1300000 | S6: 100000 | T6: 선불 | U6: 15000 | V6: 선불 | W6: 25000 | X6: 선불 | AB6: 150000 | AC6: 150000 | AD6: 150000 | AE6: 도성부동산 | AF6: 010-5184-6988 | AI6: 20/5/3부터 월세130만원으로 인하./셋탑박스하우스맨 보관 | AL6: {=_xlfn.IFS( AND($AK6<>"", M6<>0, M6<=EDATE(TODAY(),2)),"도래", AND($AK6<>"", M6<>0, M6<=EDATE(TODAY(),3)),"예정", AND($AK6<>"", M6<>0, M6<=EDATE(TODAY(),6)),"관심", TRUE,"" )} | AM6: =DAY(L6) -> 3
B7: =_xlfn.LET(_xlpm.var,◆관리정보!B7,IF(_xlpm.var<>0,_xlpm.var,"")) -> 제이앤제이 | C7: =_xlfn.LET(_xlpm.var,◆관리정보!C7,IF(_xlpm.var<>0,_xlpm.var,"")) -> 301 | D7: 차민철 | E7: =_xlfn.CONCAT(B7,C7) -> 제이앤제이301 | F7: 46102 | I7: 2037410 | L7: 45798 | M7: 45981 | N7: 940905-1069430 | O7: 010-7799-5297 | P7: 1650000 | Q7: 1650000 | S7: 120000 | T7: 선불 | U7: 25000 | V7: 선불 | W7: 25000 | X7: 선불 | AB7: 200000 | AC7: 250000 | AE7: 꿀부동산 | AF7: 010-4247-6499 | AI7: >6/23 개키움<대표님 | AL7: {=_xlfn.IFS( AND($AK7<>"", M7<>0, M7<=EDATE(TODAY(),2)),"도래", AND($AK7<>"", M7<>0, M7<=EDATE(TODAY(),3)),"예정", AND($AK7<>"", M7<>0, M7<=EDATE(TODAY(),6)),"관심", TRUE,"" )} | AM7: =DAY(L7) -> 21
B8: =_xlfn.LET(_xlpm.var,◆관리정보!B8,IF(_xlpm.var<>0,_xlpm.var,"")) -> 제이앤제이 | C8: =_xlfn.LET(_xlpm.var,◆관리정보!C8,IF(_xlpm.var<>0,_xlpm.var,"")) -> 401 | D8: 박유하 | E8: =_xlfn.CONCAT(B8,C8) -> 제이앤제이401 | F8: 46107 | L8: 45864 | M8: 45955 | N8: 990118-2035310 | O8: 010-2990-2972 | P8: 1950000 | Q8: 1950000 | S8: 150000 | T8: 선불 | U8: 30000 | V8: 선불 | W8: 25000 | X8: 선불 | AB8: 250000 | AC8: 200000 | AE8: 정담은부동산 | AF8: 010-9995-7171 | AI8: 고양이 키움 | AL8: {=_xlfn.IFS( AND($AK8<>"", M8<>0, M8<=EDATE(TODAY(),2)),"도래", AND($AK8<>"", M8<>0, M8<=EDATE(TODAY(),3)),"예정", AND($AK8<>"", M8<>0, M8<=EDATE(TODAY(),6)),"관심", TRUE,"" )} | AM8: =DAY(L8) -> 26
B9: =_xlfn.LET(_xlpm.var,◆관리정보!B9,IF(_xlpm.var<>0,_xlpm.var,"")) -> 스타빌 | C9: =_xlfn.LET(_xlpm.var,◆관리정보!C9,IF(_xlpm.var<>0,_xlpm.var,"")) -> 101 | D9: 신종호 | E9: =_xlfn.CONCAT(B9,C9) -> 스타빌101 | F9: 46127 | L9: 45884 | M9: 45975 | N9: 950528-1019712 | O9: 010-4049-0528 | P9: 650000 | Q9: 650000 | S9: 80000 | T9: 선불 | U9: 25000 | V9: 선불 | W9: 25000 | X9: 선불 | AB9: 100000 | AC9: 100000 | AE9: 참부동산 | AF9: 010-6684-0444 | AL9: {=_xlfn.IFS( AND($AK9<>"", M9<>0, M9<=EDATE(TODAY(),2)),"도래", AND($AK9<>"", M9<>0, M9<=EDATE(TODAY(),3)),"예정", AND($AK9<>"", M9<>0, M9<=EDATE(TODAY(),6)),"관심", TRUE,"" )} | AM9: =DAY(L9) -> 15
B10: =_xlfn.LET(_xlpm.var,◆관리정보!B10,IF(_xlpm.var<>0,_xlpm.var,"")) -> 스타빌 | C10: =_xlfn.LET(_xlpm.var,◆관리정보!C10,IF(_xlpm.var<>0,_xlpm.var,"")) -> 102 | D10: 주여울 | E10: =_xlfn.CONCAT(B10,C10) -> 스타빌102 | F10: 46109 | L10: 46050 | M10: 46139 | N10: 940617-2904514 | O10: 010-7771-6712 | P10: 700000 | Q10: 650000 | S10: 80000 | T10: 선불 | U10: 25000 | V10: 선불 | W10: 25000 | X10: 선불 | AB10: 100000 | AC10: 100000 | AE10: 프렌즈부동산 | AF10: 010-9903-8923 | AL10: {=_xlfn.IFS( AND($AK10<>"", M10<>0, M10<=EDATE(TODAY(),2)),"도래", AND($AK10<>"", M10<>0, M10<=EDATE(TODAY(),3)),"예정", AND($AK10<>"", M10<>0, M10<=EDATE(TODAY(),6)),"관심", TRUE,"" )} | AM10: =DAY(L10) -> 28
B11: =_xlfn.LET(_xlpm.var,◆관리정보!B11,IF(_xlpm.var<>0,_xlpm.var,"")) -> 스타빌 | C11: =_xlfn.LET(_xlpm.var,◆관리정보!C11,IF(_xlpm.var<>0,_xlpm.var,"")) -> 103 | D11: 정은혜 | E11: =_xlfn.CONCAT(B11,C11) -> 스타빌103 | F11: 46130 | L11: 45856 | M11: 45947 | N11: 880208-2910324 | O11: 010-2756-4239 | P11: 600000 | Q11: 600000 | S11: 80000 | T11: 선불 | U11: 25000 | V11: 선불 | W11: 25000 | X11: 선불 | AB11: 100000 | AC11: 100000 | AE11: 더피플부동산 | AF11: 010-3144-9736 | AI11: 지상층 나오면 연락 | AL11: {=_xlfn.IFS( AND($AK11<>"", M11<>0, M11<=EDATE(TODAY(),2)),"도래", AND($AK11<>"", M11<>0, M11<=EDATE(TODAY(),3)),"예정", AND($AK11<>"", M11<>0, M11<=EDATE(TODAY(),6)),"관심", TRUE,"" )} | AM11: =DAY(L11) -> 18
B12: =_xlfn.LET(_xlpm.var,◆관리정보!B12,IF(_xlpm.var<>0,_xlpm.var,"")) -> 스타빌 | C12: =_xlfn.LET(_xlpm.var,◆관리정보!C12,IF(_xlpm.var<>0,_xlpm.var,"")) -> 105 | D12: 황현호 | E12: =_xlfn.CONCAT(B12,C12) -> 스타빌105 | F12: 46116 | L12: 46057 | M12: 46145 | N12: 921011-1057611 | O12: 010-9996-9671 | P12: 650000 | Q12: 650000 | S12: 80000 | T12: 선불 | U12: 25000 | V12: 선불 | W12: 25000 | X12: 선불 | AB12: 100000 | AC12: 100000 | AE12: 정담부동산 | AF12: 010-3637-3578 | AL12: {=_xlfn.IFS( AND($AK12<>"", M12<>0, M12<=EDATE(TODAY(),2)),"도래", AND($AK12<>"", M12<>0, M12<=EDATE(TODAY(),3)),"예정", AND($AK12<>"", M12<>0, M12<=EDATE(TODAY(),6)),"관심", TRUE,"" )} | AM12: =DAY(L12) -> 4
B13: =_xlfn.LET(_xlpm.var,◆관리정보!B13,IF(_xlpm.var<>0,_xlpm.var,"")) -> 스타빌 | C13: =_xlfn.LET(_xlpm.var,◆관리정보!C13,IF(_xlpm.var<>0,_xlpm.var,"")) -> 201 | D13: 이지현 | E13: =_xlfn.CONCAT(B13,C13) -> 스타빌201 | F13: 46116 | L13: 43955 | M13: 44046 | N13: 841123-2058711 | O13: 010-5050-9375 | P13: 650000 | Q13: 650000 | S13: 60000 | T13: 선불 | U13: 20000 | V13: 선불 | W13: 25000 | X13: 선불 | AB13: 100000 | AC13: 100000 | AD13: 50000 | AE13: 정담은부동산 | AF13: 010-2941-9295 | AI13: 12/4 월세5만,수도5천인상 | AL13: {=_xlfn.IFS( AND($AK13<>"", M13<>0, M13<=EDATE(TODAY(),2)),"도래", AND($AK13<>"", M13<>0, M13<=EDATE(TODAY(),3)),"예정", AND($AK13<>"", M13<>0, M13<=EDATE(TODAY(),6)),"관심", TRUE,"" )} | AM13: =DAY(L13) -> 4
B14: =_xlfn.LET(_xlpm.var,◆관리정보!B14,IF(_xlpm.var<>0,_xlpm.var,"")) -> 스타빌 | C14: =_xlfn.LET(_xlpm.var,◆관리정보!C14,IF(_xlpm.var<>0,_xlpm.var,"")) -> 202 | D14: 이지람 | E14: =_xlfn.CONCAT(B14,C14) -> 스타빌202 | F14: 46110 | L14: 45594 | M14: 45685 | N14: 930807-1200225 | O14: 010-6680-7123 | P14: 750000 | Q14: 750000 | S14: 80000 | T14: 선불 | U14: 25000 | V14: 선불 | W14: 25000 | X14: 선불 | AB14: 100000 | AC14: 100000 | AE14: 리스펙부동산 | AF14: 010-5959-8200 | AL14: {=_xlfn.IFS( AND($AK14<>"", M14<>0, M14<=EDATE(TODAY(),2)),"도래", AND($AK14<>"", M14<>0, M14<=EDATE(TODAY(),3)),"예정", AND($AK14<>"", M14<>0, M14<=EDATE(TODAY(),6)),"관심", TRUE,"" )} | AM14: =DAY(L14) -> 29
B15: =_xlfn.LET(_xlpm.var,◆관리정보!B15,IF(_xlpm.var<>0,_xlpm.var,"")) -> 스타빌 | C15: =_xlfn.LET(_xlpm.var,◆관리정보!C15,IF(_xlpm.var<>0,_xlpm.var,"")) -> 203 | D15: 김성호 | E15: =_xlfn.CONCAT(B15,C15) -> 스타빌203 | F15: 46108 | L15: 45743 | M15: 45834 | N15: 900123-1748144 | O15: 010-2049-6191 | P15: 750000 | Q15: 700000 | S15: 80000 | T15: 선불 | U15: 25000 | V15: 선불 | W15: 25000 | X15: 선불 | AB15: 100000 | AC15: 100000 | AE15: 더피플부동산 | AF15: 010-3980-1211 | AL15: {=_xlfn.IFS( AND($AK15<>"", M15<>0, M15<=EDATE(TODAY(),2)),"도래", AND($AK15<>"", M15<>0, M15<=EDATE(TODAY(),3)),"예정", AND($AK15<>"", M15<>0, M15<=EDATE(TODAY(),6)),"관심", TRUE,"" )} | AM15: =DAY(L15) -> 27
B16: =_xlfn.LET(_xlpm.var,◆관리정보!B16,IF(_xlpm.var<>0,_xlpm.var,"")) -> 스타빌 | C16: =_xlfn.LET(_xlpm.var,◆관리정보!C16,IF(_xlpm.var<>0,_xlpm.var,"")) -> 205 | D16: 김소희 | E16: =_xlfn.CONCAT(B16,C16) -> 스타빌205 | F16: 46123 | L16: 45393 | M16: 45483 | N16: 001217-4151612 | O16: 010-7631-2483 | P16: 700000 | Q16: 700000 | S16: 80000 | T16: 선불 | U16: 20000 | V16: 선불 | W16: 25000 | X16: 선불 | AB16: 100000 | AC16: 100000 | AE16: 정담은부동산 | AF16: 010-9042-8412 | AL16: {=_xlfn.IFS( AND($AK16<>"", M16<>0, M16<=EDATE(TODAY(),2)),"도래", AND($AK16<>"", M16<>0, M16<=EDATE(TODAY(),3)),"예정", AND($AK16<>"", M16<>0, M16<=EDATE(TODAY(),6)),"관심", TRUE,"" )} | AM16: =DAY(L16) -> 11
B17: =_xlfn.LET(_xlpm.var,◆관리정보!B17,IF(_xlpm.var<>0,_xlpm.var,"")) -> 스타빌 | C17: =_xlfn.LET(_xlpm.var,◆관리정보!C17,IF(_xlpm.var<>0,_xlpm.var,"")) -> 301 | D17: 박성윤 | E17: =_xlfn.CONCAT(B17,C17) -> 스타빌301 | F17: 46128 | L17: 46007 | M17: 46096 | N17: 000512-3018714 | O17: 010-4998-6676 | P17: 700000 | Q17: 700000 | S17: 80000 | T17: 선불 | U17: 25000 | V17: 선불 | W17: 25000 | X17: 선불 | AB17: 100000 | AC17: 100000 | AE17: 퍼스트부동산 | AF17: 010-5702-2303 | AL17: {=_xlfn.IFS( AND($AK17<>"", M17<>0, M17<=EDATE(TODAY(),2)),"도래", AND($AK17<>"", M17<>0, M17<=EDATE(TODAY(),3)),"예정", AND($AK17<>"", M17<>0, M17<=EDATE(TODAY(),6)),"관심", TRUE,"" )} | AM17: =DAY(L17) -> 16
B18: =_xlfn.LET(_xlpm.var,◆관리정보!B18,IF(_xlpm.var<>0,_xlpm.var,"")) -> 스타빌 | C18: =_xlfn.LET(_xlpm.var,◆관리정보!C18,IF(_xlpm.var<>0,_xlpm.var,"")) -> 302 | D18: 홍윤미 | E18: =_xlfn.CONCAT(B18,C18) -> 스타빌302 | F18: 46125 | L18: 44299 | M18: 44481 | N18: 810715-2402711 | O18: 010-4187-3400 | P18: 650000 | Q18: 650000 | S18: 60000 | T18: 선불 | U18: 15000 | V18: 선불 | W18: 25000 | X18: 선불 | AB18: 100000 | AC18: 100000 | AD18: 50000 | AE18: 반하다부동산 | AF18: 010-4087-8706 | AL18: {=_xlfn.IFS( AND($AK18<>"", M18<>0, M18<=EDATE(TODAY(),2)),"도래", AND($AK18<>"", M18<>0, M18<=EDATE(TODAY(),3)),"예정", AND($AK18<>"", M18<>0, M18<=EDATE(TODAY(),6)),"관심", TRUE,"" )} | AM18: =DAY(L18) -> 13
B19: =_xlfn.LET(_xlpm.var,◆관리정보!B19,IF(_xlpm.var<>0,_xlpm.var,"")) -> 스타빌 | C19: =_xlfn.LET(_xlpm.var,◆관리정보!C19,IF(_xlpm.var<>0,_xlpm.var,"")) -> 303 | D19: 김세아 | E19: =_xlfn.CONCAT(B19,C19) -> 스타빌303 | F19: 46103 | J19: 902720 | L19: 46044 | M19: 46133 | N19: 070622-4274210 | O19: 010-5635-8622 | P19: 700000 | Q19: 700000 | S19: 80000 | T19: 선불 | U19: 25000 | V19: 선불 | W19: 25000 | X19: 선불 | AB19: 100000 | AC19: 100000 | AE19: 정담부동산 | AF19: 010-9995-7171 | AL19: {=_xlfn.IFS( AND($AK19<>"", M19<>0, M19<=EDATE(TODAY(),2)),"도래", AND($AK19<>"", M19<>0, M19<=EDATE(TODAY(),3)),"예정", AND($AK19<>"", M19<>0, M19<=EDATE(TODAY(),6)),"관심", TRUE,"" )} | AM19: =DAY(L19) -> 22
B20: =_xlfn.LET(_xlpm.var,◆관리정보!B20,IF(_xlpm.var<>0,_xlpm.var,"")) -> 스타빌 | C20: =_xlfn.LET(_xlpm.var,◆관리정보!C20,IF(_xlpm.var<>0,_xlpm.var,"")) -> 305 | D20: 박현진 | E20: =_xlfn.CONCAT(B20,C20) -> 스타빌305 | F20: 46106 | J20: 947080 | L20: 45802 | M20: 45893 | N20: 890227-2851512 | O20: 010-9233-7410 | P20: 700000 | Q20: 700000 | S20: 80000 | T20: 선불 | U20: 25000 | V20: 선불 | W20: 25000 | X20: 선불 | AB20: 100000 | AC20: 100000 | AE20: SD부동산 | AF20: 010-2261-3125 | AL20: {=_xlfn.IFS( AND($AK20<>"", M20<>0, M20<=EDATE(TODAY(),2)),"도래", AND($AK20<>"", M20<>0, M20<=EDATE(TODAY(),3)),"예정", AND($AK20<>"", M20<>0, M20<=EDATE(TODAY(),6)),"관심", TRUE,"" )} | AM20: =DAY(L20) -> 25
B21: =_xlfn.LET(_xlpm.var,◆관리정보!B21,IF(_xlpm.var<>0,_xlpm.var,"")) -> 스타빌 | C21: =_xlfn.LET(_xlpm.var,◆관리정보!C21,IF(_xlpm.var<>0,_xlpm.var,"")) -> 401 | D21: 박유림 | E21: =_xlfn.CONCAT(B21,C21) -> 스타빌401 | F21: 46121 | L21: 45208 | M21: 45299 | N21: 980408-2861912 | O21: 010-2755-0364 | P21: 700000 | Q21: 700000 | S21: 80000 | T21: 선불 | U21: 20000 | V21: 선불 | W21: 25000 | X21: 선불 | AB21: 100000 | AC21: 100000 | AE21: 정담은부동산 | AF21: 010-6467-7663 | AL21: {=_xlfn.IFS( AND($AK21<>"", M21<>0, M21<=EDATE(TODAY(),2)),"도래", AND($AK21<>"", M21<>0, M21<=EDATE(TODAY(),3)),"예정", AND($AK21<>"", M21<>0, M21<=EDATE(TODAY(),6)),"관심", TRUE,"" )} | AM21: =DAY(L21) -> 9
B22: =_xlfn.LET(_xlpm.var,◆관리정보!B22,IF(_xlpm.var<>0,_xlpm.var,"")) -> 스타빌 | C22: =_xlfn.LET(_xlpm.var,◆관리정보!C22,IF(_xlpm.var<>0,_xlpm.var,"")) -> 402 | D22: 김혜서 | E22: =_xlfn.CONCAT(B22,C22) -> 스타빌402 | F22: 46115 | L22: 46056 | M22: 46144 | N22: 020409-4096419 | O22: 010-4014-8167 | P22: 750000 | Q22: 750000 | S22: 80000 | T22: 선불 | U22: 25000 | V22: 선불 | W22: 25000 | X22: 선불 | AB22: 100000 | AC22: 100000 | AE22: SD부동산 | AF22: 010-2831-6479 | AL22: {=_xlfn.IFS( AND($AK22<>"", M22<>0, M22<=EDATE(TODAY(),2)),"도래", AND($AK22<>"", M22<>0, M22<=EDATE(TODAY(),3)),"예정", AND($AK22<>"", M22<>0, M22<=EDATE(TODAY(),6)),"관심", TRUE,"" )} | AM22: =DAY(L22) -> 3
B23: =_xlfn.LET(_xlpm.var,◆관리정보!B23,IF(_xlpm.var<>0,_xlpm.var,"")) -> 스타빌 | C23: =_xlfn.LET(_xlpm.var,◆관리정보!C23,IF(_xlpm.var<>0,_xlpm.var,"")) -> 403 | D23: 송예준 | E23: =_xlfn.CONCAT(B23,C23) -> 스타빌403 | F23: 46104 | J23: 991510 | L23: 45923 | M23: 46013 | N23: 960601-1079816 | O23: 010-2458-9765 | P23: 750000 | Q23: 750000 | S23: 80000 | T23: 선불 | U23: 25000 | V23: 선불 | W23: 25000 | X23: 선불 | AB23: 100000 | AC23: 100000 | AE23: SD부동산 | AF23: 010-9489-3929 | AL23: {=_xlfn.IFS( AND($AK23<>"", M23<>0, M23<=EDATE(TODAY(),2)),"도래", AND($AK23<>"", M23<>0, M23<=EDATE(TODAY(),3)),"예정", AND($AK23<>"", M23<>0, M23<=EDATE(TODAY(),6)),"관심", TRUE,"" )} | AM23: =DAY(L23) -> 23
B24: =_xlfn.LET(_xlpm.var,◆관리정보!B24,IF(_xlpm.var<>0,_xlpm.var,"")) -> 스타빌 | C24: =_xlfn.LET(_xlpm.var,◆관리정보!C24,IF(_xlpm.var<>0,_xlpm.var,"")) -> 405 | D24: 고연희 | E24: =_xlfn.CONCAT(B24,C24) -> 스타빌405 | F24: 46097 | J24: =1006030-1370 -> 1004660 | L24: 46007 | M24: 46096 | N24: 751124-2057743 | O24: 010-7570-5846 | P24: 750000 | Q24: 700000 | S24: 80000 | T24: 선불 | U24: 25000 | V24: 선불 | W24: 25000 | X24: 선불 | AB24: 100000 | AC24: 100000 | AE24: 프렌즈부동산 | AF24: 010-9903-8923 | AL24: {=_xlfn.IFS( AND($AK24<>"", M24<>0, M24<=EDATE(TODAY(),2)),"도래", AND($AK24<>"", M24<>0, M24<=EDATE(TODAY(),3)),"예정", AND($AK24<>"", M24<>0, M24<=EDATE(TODAY(),6)),"관심", TRUE,"" )} | AM24: =DAY(L24) -> 16
B25: =_xlfn.LET(_xlpm.var,◆관리정보!B25,IF(_xlpm.var<>0,_xlpm.var,"")) -> 아페이론 | C25: =_xlfn.LET(_xlpm.var,◆관리정보!C25,IF(_xlpm.var<>0,_xlpm.var,"")) -> 101 | D25: 한유진 | E25: =_xlfn.CONCAT(B25,C25) -> 아페이론101 | F25: 46116 | L25: 45781 | M25: 45872 | N25: 001206-4937211 | O25: 010-8652-6254 | P25: 1200000 | Q25: 1200000 | S25: 80000 | T25: 선불 | U25: 25000 | V25: 선불 | W25: 25000 | X25: 선불 | AB25: 180000 | AC25: 200000 | AE25: 강남더힐부동산 | AF25: 010-8459-3711 | AL25: {=_xlfn.IFS( AND($AK25<>"", M25<>0, M25<=EDATE(TODAY(),2)),"도래", AND($AK25<>"", M25<>0, M25<=EDATE(TODAY(),3)),"예정", AND($AK25<>"", M25<>0, M25<=EDATE(TODAY(),6)),"관심", TRUE,"" )} | AM25: =DAY(L25) -> 4
B26: =_xlfn.LET(_xlpm.var,◆관리정보!B26,IF(_xlpm.var<>0,_xlpm.var,"")) -> 아페이론 | C26: =_xlfn.LET(_xlpm.var,◆관리정보!C26,IF(_xlpm.var<>0,_xlpm.var,"")) -> 102 | D26: 신현식 | E26: =_xlfn.CONCAT(B26,C26) -> 아페이론102 | F26: 46121 | L26: 45147 | M26: 45238 | N26: 960321-1030010 | O26: 010-8847-3777 | P26: 1250000 | Q26: 1250000 | S26: 100000 | T26: 선불 | U26: 25000 | V26: 선불 | W26: 25000 | X26: 선불 | AA26: 30부9342 | AB26: 150000 | AC26: 200000 | AE26: 정담은부동산 | AF26: 010-6717-7107 | AL26: {=_xlfn.IFS( AND($AK26<>"", M26<>0, M26<=EDATE(TODAY(),2)),"도래", AND($AK26<>"", M26<>0, M26<=EDATE(TODAY(),3)),"예정", AND($AK26<>"", M26<>0, M26<=EDATE(TODAY(),6)),"관심", TRUE,"" )} | AM26: =DAY(L26) -> 9
B27: =_xlfn.LET(_xlpm.var,◆관리정보!B27,IF(_xlpm.var<>0,_xlpm.var,"")) -> 아페이론 | C27: =_xlfn.LET(_xlpm.var,◆관리정보!C27,IF(_xlpm.var<>0,_xlpm.var,"")) -> 103 | D27: 김지은 | E27: =_xlfn.CONCAT(B27,C27) -> 아페이론103 | F27: 46098 | J27: =1474460-700000 -> 774460 | L27: 45308 | M27: 45398 | N27: 950317-2182415 | O27: 010-2861-0889 | P27: 1200000 | Q27: 1200000 | S27: 80000 | T27: 선불 | U27: 25000 | V27: 선불 | W27: 25000 | X27: 선불 | AB27: 150000 | AC27: 200000 | AE27: 투유부동산 | AF27: 010-7345-7907 | AI27: 1/7 퇴실 취소 ( 퇴실 일자 확인하여 일주일 전에 회사로 전화 달라 안내 함) | AL27: {=_xlfn.IFS( AND($AK27<>"", M27<>0, M27<=EDATE(TODAY(),2)),"도래", AND($AK27<>"", M27<>0, M27<=EDATE(TODAY(),3)),"예정", AND($AK27<>"", M27<>0, M27<=EDATE(TODAY(),6)),"관심", TRUE,"" )} | AM27: =DAY(L27) -> 17
B28: =_xlfn.LET(_xlpm.var,◆관리정보!B28,IF(_xlpm.var<>0,_xlpm.var,"")) -> 아페이론 | C28: =_xlfn.LET(_xlpm.var,◆관리정보!C28,IF(_xlpm.var<>0,_xlpm.var,"")) -> 104 | D28: 김도경 | E28: =_xlfn.CONCAT(B28,C28) -> 아페이론104 | F28: 46114 | L28: 42157 | M28: 42248 | N28: 931023-2247117 | O28: 010-6825-5997 | P28: 1300000 | Q28: 1300000 | S28: 100000 | T28: 선불 | U28: 20000 | V28: 후불 | W28: 25000 | X28: 후불 | AB28: 80000 | AC28: 200000 | AD28: 100000 | AE28: 타임부동산 | AF28: 010-8678-1666 | AI28: (고양이2마리,벽지손상심한상태)12/2 수도 5천,관리비2만인상 (이전번호 : 010-2576-6586) | AL28: {=_xlfn.IFS( AND($AK28<>"", M28<>0, M28<=EDATE(TODAY(),2)),"도래", AND($AK28<>"", M28<>0, M28<=EDATE(TODAY(),3)),"예정", AND($AK28<>"", M28<>0, M28<=EDATE(TODAY(),6)),"관심", TRUE,"" )} | AM28: =DAY(L28) -> 2
B29: =_xlfn.LET(_xlpm.var,◆관리정보!B29,IF(_xlpm.var<>0,_xlpm.var,"")) -> 아페이론 | C29: =_xlfn.LET(_xlpm.var,◆관리정보!C29,IF(_xlpm.var<>0,_xlpm.var,"")) -> 105 | D29: 김태오 | E29: =_xlfn.CONCAT(B29,C29) -> 아페이론105 | F29: 46127 | J29: =1581110-(500000+500000+500000+90000) -> -8890 | L29: 45672 | M29: 45761 | N29: 920103-1870314 | O29: 010-3425-1062 | P29: 1250000 | Q29: 1250000 | S29: 80000 | T29: 선불 | U29: 25000 | V29: 선불 | W29: 25000 | X29: 선불 | AB29: 180000 | AC29: 200000 | AE29: dh부동산 | AF29: 010-5719-2838 | AL29: {=_xlfn.IFS( AND($AK29<>"", M29<>0, M29<=EDATE(TODAY(),2)),"도래", AND($AK29<>"", M29<>0, M29<=EDATE(TODAY(),3)),"예정", AND($AK29<>"", M29<>0, M29<=EDATE(TODAY(),6)),"관심", TRUE,"" )} | AM29: =DAY(L29) -> 15
B30: =_xlfn.LET(_xlpm.var,◆관리정보!B30,IF(_xlpm.var<>0,_xlpm.var,"")) -> 아페이론 | C30: =_xlfn.LET(_xlpm.var,◆관리정보!C30,IF(_xlpm.var<>0,_xlpm.var,"")) -> 201 | D30: 박유빈 | E30: =_xlfn.CONCAT(B30,C30) -> 아페이론201 | F30: 46091 | J30: =1467900-750000 -> 717900 | K30: 22500 | L30: 46001 | M30: 46090 | N30: 941213-1731115 | O30: 010-7684-8191 | P30: 1200000 | Q30: 1200000 | S30: 80000 | T30: 선불 | U30: 25000 | V30: 선불 | W30: 25000 | X30: 선불 | AB30: 180000 | AC30: 200000 | AE30: 투유부동산 | AF30: 010-4768-6559 | AL30: {=_xlfn.IFS( AND($AK30<>"", M30<>0, M30<=EDATE(TODAY(),2)),"도래", AND($AK30<>"", M30<>0, M30<=EDATE(TODAY(),3)),"예정", AND($AK30<>"", M30<>0, M30<=EDATE(TODAY(),6)),"관심", TRUE,"" )} | AM30: =DAY(L30) -> 10
B31: =_xlfn.LET(_xlpm.var,◆관리정보!B31,IF(_xlpm.var<>0,_xlpm.var,"")) -> 아페이론 | C31: =_xlfn.LET(_xlpm.var,◆관리정보!C31,IF(_xlpm.var<>0,_xlpm.var,"")) -> 202 | D31: 박채원 | E31: =_xlfn.CONCAT(B31,C31) -> 아페이론202 | F31: 46128 | L31: 46097 | M31: 46188 | N31: 040512-4164613 | O31: 010-4713-3261 | P31: 1250000 | Q31: 1200000 | S31: 80000 | T31: 선불 | U31: 25000 | V31: 선불 | W31: 25000 | X31: 선불 | AB31: 180000 | AC31: 200000 | AE31: 정담은부동산 | AF31: 010-6467-7663 | AL31: {=_xlfn.IFS( AND($AK31<>"", M31<>0, M31<=EDATE(TODAY(),2)),"도래", AND($AK31<>"", M31<>0, M31<=EDATE(TODAY(),3)),"예정", AND($AK31<>"", M31<>0, M31<=EDATE(TODAY(),6)),"관심", TRUE,"" )} | AM31: =DAY(L31) -> 16
B32: =_xlfn.LET(_xlpm.var,◆관리정보!B32,IF(_xlpm.var<>0,_xlpm.var,"")) -> 아페이론 | C32: =_xlfn.LET(_xlpm.var,◆관리정보!C32,IF(_xlpm.var<>0,_xlpm.var,"")) -> 203 | D32: 이준우 | E32: =_xlfn.CONCAT(B32,C32) -> 아페이론203 | F32: 46095 | J32: =1540100-540100-200000-200000-100000 -> 500000 | K32: 15000 | L32: 45579 | M32: 45670 | N32: 020801-3170223 | O32: 010-3234-5260 | P32: 1300000 | Q32: 1300000 | S32: 80000 | T32: 선불 | U32: 25000 | V32: 선불 | W32: 25000 | X32: 선불 | AB32: 180000 | AC32: 200000 | AE32: 강남센터부동산 | AF32: 010-9042-8412 | AI32: 기존 연락처 : 010-7521-5260 | AL32: {=_xlfn.IFS( AND($AK32<>"", M32<>0, M32<=EDATE(TODAY(),2)),"도래", AND($AK32<>"", M32<>0, M32<=EDATE(TODAY(),3)),"예정", AND($AK32<>"", M32<>0, M32<=EDATE(TODAY(),6)),"관심", TRUE,"" )} | AM32: =DAY(L32) -> 14
B33: =_xlfn.LET(_xlpm.var,◆관리정보!B33,IF(_xlpm.var<>0,_xlpm.var,"")) -> 아페이론 | C33: =_xlfn.LET(_xlpm.var,◆관리정보!C33,IF(_xlpm.var<>0,_xlpm.var,"")) -> 204 | D33: 권영우 | E33: =_xlfn.CONCAT(B33,C33) -> 아페이론204 | F33: 46100 | J33: 1385850 | L33: 45796 | M33: 45887 | N33: 861220-1068919 | O33: 010-7936-0506 | P33: 1200000 | Q33: 1200000 | S33: 100000 | T33: 선불 | U33: 25000 | V33: 선불 | W33: 25000 | X33: 선불 | AA33: 13버2621 | AB33: 180000 | AC33: 200000 | AE33: 하이앤드부동산 | AF33: 010-8243-2387 | AI33: 개 키움 1.6 | AL33: {=_xlfn.IFS( AND($AK33<>"", M33<>0, M33<=EDATE(TODAY(),2)),"도래", AND($AK33<>"", M33<>0, M33<=EDATE(TODAY(),3)),"예정", AND($AK33<>"", M33<>0, M33<=EDATE(TODAY(),6)),"관심", TRUE,"" )} | AM33: =DAY(L33) -> 19
B34: =_xlfn.LET(_xlpm.var,◆관리정보!B34,IF(_xlpm.var<>0,_xlpm.var,"")) -> 아페이론 | C34: =_xlfn.LET(_xlpm.var,◆관리정보!C34,IF(_xlpm.var<>0,_xlpm.var,"")) -> 205 | D34: 정현민 | E34: =_xlfn.CONCAT(B34,C34) -> 아페이론205 | F34: 46101 | J34: 1438800 | L34: 46042 | M34: 46131 | N34: 000607-3241016 | O34: 010-8001-5981 | P34: 1200000 | Q34: 1200000 | S34: 80000 | T34: 선불 | U34: 25000 | V34: 선불 | W34: 25000 | X34: 선불 | AA34: 367버1207 | AB34: 180000 | AC34: 200000 | AE34: 프렌즈부동산 | AF34: 010-4022-7333 | AL34: {=_xlfn.IFS( AND($AK34<>"", M34<>0, M34<=EDATE(TODAY(),2)),"도래", AND($AK34<>"", M34<>0, M34<=EDATE(TODAY(),3)),"예정", AND($AK34<>"", M34<>0, M34<=EDATE(TODAY(),6)),"관심", TRUE,"" )} | AM34: =DAY(L34) -> 20
B35: =_xlfn.LET(_xlpm.var,◆관리정보!B35,IF(_xlpm.var<>0,_xlpm.var,"")) -> 다존하우스 | C35: =_xlfn.LET(_xlpm.var,◆관리정보!C35,IF(_xlpm.var<>0,_xlpm.var,"")) -> 201 | D35: 권지현 | E35: =_xlfn.CONCAT(B35,C35) -> 다존하우스201 | F35: 46101 | J35: 619310 | L35: 45950 | M35: 46010 | N35: 680402-2350410 | O35: 010-5879-9657 | P35: 500000 | Q35: 500000 | S35: 70000 | T35: 선불 | AB35: 80000 | AC35: 100000 | AE35: 골든부동산 | AF35: 010-4783-3367 | AL35: {=_xlfn.IFS( AND($AK35<>"", M35<>0, M35<=EDATE(TODAY(),2)),"도래", AND($AK35<>"", M35<>0, M35<=EDATE(TODAY(),3)),"예정", AND($AK35<>"", M35<>0, M35<=EDATE(TODAY(),6)),"관심", TRUE,"" )} | AM35: =DAY(L35) -> 20
B36: =_xlfn.LET(_xlpm.var,◆관리정보!B36,IF(_xlpm.var<>0,_xlpm.var,"")) -> 다존하우스 | C36: =_xlfn.LET(_xlpm.var,◆관리정보!C36,IF(_xlpm.var<>0,_xlpm.var,"")) -> 202 | D36: 퇴실 | E36: =_xlfn.CONCAT(B36,C36) -> 다존하우스202 | AI36: 누수가 확인 하려면 입주 후 상황봐야 알 것 같다고 하십 | AL36: {=_xlfn.IFS( AND($AK36<>"", M36<>0, M36<=EDATE(TODAY(),2)),"도래", AND($AK36<>"", M36<>0, M36<=EDATE(TODAY(),3)),"예정", AND($AK36<>"", M36<>0, M36<=EDATE(TODAY(),6)),"관심", TRUE,"" )} | AM36: =DAY(L36) -> 0
B37: =_xlfn.LET(_xlpm.var,◆관리정보!B37,IF(_xlpm.var<>0,_xlpm.var,"")) -> 다존하우스 | C37: =_xlfn.LET(_xlpm.var,◆관리정보!C37,IF(_xlpm.var<>0,_xlpm.var,"")) -> 203 | D37: 박건희 | E37: =_xlfn.CONCAT(B37,C37) -> 다존하우스203 | F37: 46130 | L37: 46009 | M37: 46098 | N37: 981109-1070829 | O37: 010-2575-0544 | P37: 500000 | Q37: 400000 | S37: 70000 | T37: 선불 | AB37: 80000 | AC37: 100000 | AE37: 연부동산 | AF37: 010-2612-9607 | AL37: {=_xlfn.IFS( AND($AK37<>"", M37<>0, M37<=EDATE(TODAY(),2)),"도래", AND($AK37<>"", M37<>0, M37<=EDATE(TODAY(),3)),"예정", AND($AK37<>"", M37<>0, M37<=EDATE(TODAY(),6)),"관심", TRUE,"" )} | AM37: =DAY(L37) -> 18
B38: =_xlfn.LET(_xlpm.var,◆관리정보!B38,IF(_xlpm.var<>0,_xlpm.var,"")) -> 다존하우스 | C38: =_xlfn.LET(_xlpm.var,◆관리정보!C38,IF(_xlpm.var<>0,_xlpm.var,"")) -> 205 | D38: 미노출 | E38: =_xlfn.CONCAT(B38,C38) -> 다존하우스205 | AI38: 도배완료 | AL38: {=_xlfn.IFS( AND($AK38<>"", M38<>0, M38<=EDATE(TODAY(),2)),"도래", AND($AK38<>"", M38<>0, M38<=EDATE(TODAY(),3)),"예정", AND($AK38<>"", M38<>0, M38<=EDATE(TODAY(),6)),"관심", TRUE,"" )} | AM38: =DAY(L38) -> 0
B39: =_xlfn.LET(_xlpm.var,◆관리정보!B39,IF(_xlpm.var<>0,_xlpm.var,"")) -> 다존하우스 | C39: =_xlfn.LET(_xlpm.var,◆관리정보!C39,IF(_xlpm.var<>0,_xlpm.var,"")) -> 206 | D39: 소현수 | E39: =_xlfn.CONCAT(B39,C39) -> 다존하우스206 | F39: 46089 | J39: 593470 | K39: 20000 | L39: 45999 | M39: 46088 | N39: 980219-1055016 | O39: 010-7643-5148 | P39: 500000 | Q39: 400000 | S39: 70000 | T39: 선불 | AB39: 80000 | AC39: 100000 | AE39: 연부동산 | AF39: 010-8589-2903 | AI39: 2/26누수[천장도배] / 010-9136-2103(부모님) / | AL39: {=_xlfn.IFS( AND($AK39<>"", M39<>0, M39<=EDATE(TODAY(),2)),"도래", AND($AK39<>"", M39<>0, M39<=EDATE(TODAY(),3)),"예정", AND($AK39<>"", M39<>0, M39<=EDATE(TODAY(),6)),"관심", TRUE,"" )} | AM39: =DAY(L39) -> 8
B40: =_xlfn.LET(_xlpm.var,◆관리정보!B40,IF(_xlpm.var<>0,_xlpm.var,"")) -> 다존하우스 | C40: =_xlfn.LET(_xlpm.var,◆관리정보!C40,IF(_xlpm.var<>0,_xlpm.var,"")) -> 207 | D40: 건물주 | E40: =_xlfn.CONCAT(B40,C40) -> 다존하우스207 | AL40: {=_xlfn.IFS( AND($AK40<>"", M40<>0, M40<=EDATE(TODAY(),2)),"도래", AND($AK40<>"", M40<>0, M40<=EDATE(TODAY(),3)),"예정", AND($AK40<>"", M40<>0, M40<=EDATE(TODAY(),6)),"관심", TRUE,"" )} | AM40: =DAY(L40) -> 0
...

Sheet □공실현황
A1: □ 공실현황 | G1: =TODAY() -> 46099 | Q1: 호실비밀번호 | R1: 5500
G2: 단기 | H2: 근생 | I2: 일반 | J2: 미노출 | K2: 공실 | L2: =COUNTA(C6:C50) -> 22 | Q2: 다존하우스 | R2: 9216 | T2: ■ 기초 값
G3: =COUNTIF($N$6:$N$50,G2) -> 10 | H3: =COUNTIF($N$6:$N$50,"상가") -> 5 | I3: =COUNTIF($N$6:$N$50,I2) -> 6 | J3: =COUNTA($O$6:$O$50) -> 8 | Q3: 옥당빌라 | R3: 1235
A4: 중개수수료 | C4: 건물명 | D4: 호수 | E4: 현관비번 | F4: 예치금 | G4: 월세 | H4: NEGO | I4: 관리비 | J4: 수도 | K4: 케이블 | L4: 퇴실비 | M4: 공실 | O4: ="미노출 (" & COUNTA(O6:O50) & ")" -> 미노출 (8) | Q4: 현관 비밀번호 | T4: 중개수수료 | V4: 건물명 | W4: 예치금 | X4: 월세 | Y4: NEGO | Z4: 관리비 | AA4: 수도 | AB4: 케이블 | AC4: 퇴실청소비 | AD4: 룸 형태
A5: 추가 | B5: 기본 | M5: 기간 | T5: 추가 | U5: 기본
A6: =IF($C6="","",_xlfn.XLOOKUP(_xlfn.CONCAT($C6,$D6),$V:$V,T:T,"",0)) | B6: =IF($C6="","",_xlfn.XLOOKUP(_xlfn.CONCAT($C6,$D6),$V:$V,U:U,"",0)) -> 10 | C6: {=_xlfn._xlws.FILTER(■입주정보!B4:B1000,(■입주정보!$D4:$D1000="퇴실") + (■입주정보!$AJ4:$AJ1000="연결"))} -> 다존하우스 | D6: {=_xlfn._xlws.FILTER(■입주정보!C4:C1000,(■입주정보!$D4:$D1000="퇴실") + (■입주정보!$AJ4:$AJ1000="연결"))} -> 202 | E6: =IF(C6="","",_xlfn.XLOOKUP(C6,$Q$6:$Q$100,$R$6:$R$100,"",0)) -> 731024# | F6: =IF($C6="","",_xlfn.XLOOKUP(_xlfn.CONCAT($C6,$D6),$V:$V,W:W,"",0)) -> 50 | G6: =IF($C6="","",_xlfn.XLOOKUP(_xlfn.CONCAT($C6,$D6),$V:$V,X:X,"",0)) -> 50 | H6: =IF($C6="","",_xlfn.XLOOKUP(_xlfn.CONCAT($C6,$D6),$V:$V,Y:Y,"",0)) -> 50 | I6: =IF($C6="","",_xlfn.XLOOKUP(_xlfn.CONCAT($C6,$D6),$V:$V,Z:Z,"",0)) -> 7 | J6: =IF($C6="","",_xlfn.XLOOKUP(_xlfn.CONCAT($C6,$D6),$V:$V,AA:AA,"",0)) -> 포함 | K6: =IF($C6="","",_xlfn.XLOOKUP(_xlfn.CONCAT($C6,$D6),$V:$V,AB:AB,"",0)) -> 포함 | L6: =IF($C6="","",_xlfn.XLOOKUP(_xlfn.CONCAT($C6,$D6),$V:$V,AC:AC,"",0)) -> 8 | M6: {=_xlfn.LET(_xlpm.퇴실일, _xlfn.XLOOKUP(_xlfn.CONCAT(C6,D6),■퇴실정보!$B$4:$B$1000&■퇴실정보!$C$4:$C$1000,■퇴실정보!$E$4:$E$1000,0,0,-1),IF(TODAY()-_xlpm.퇴실일>1000,0,TODAY()-_xlpm.퇴실일))} -> 0 | N6: {=IF($C6="","",_xlfn.XLOOKUP(_xlfn.CONCAT($C6,$D6),◆관리정보!$B:$B & ◆관리정보!$C:$C,◆관리정보!$J:$J))} -> 단기 | O6: {=_xlfn._xlws.FILTER(■입주정보!B4:B1000 & " " & ■입주정보!C4:C1000,(■입주정보!$D4:$D1000="미노출"))} -> 다존하우스 205 | Q6: 제이앤제이 | R6: OPEN | U6: 10 | V6: 제이앤제이B01 | W6: 70 | X6: 70 | Y6: 65 | Z6: 7 | AA6: 2.5 | AB6: 2.5 | AC6: 10 | AD6: 원룸
A7: =IF($C7="","",_xlfn.XLOOKUP(_xlfn.CONCAT($C7,$D7),$V:$V,T:T,"",0)) | B7: =IF($C7="","",_xlfn.XLOOKUP(_xlfn.CONCAT($C7,$D7),$V:$V,U:U,"",0)) -> 10 | C7: 다존하우스 | D7: 509 | E7: =IF(C7="","",_xlfn.XLOOKUP(C7,$Q$6:$Q$100,$R$6:$R$100,"",0)) -> 731024# | F7: =IF($C7="","",_xlfn.XLOOKUP(_xlfn.CONCAT($C7,$D7),$V:$V,W:W,"",0)) -> 55 | G7: =IF($C7="","",_xlfn.XLOOKUP(_xlfn.CONCAT($C7,$D7),$V:$V,X:X,"",0)) -> 55 | H7: =IF($C7="","",_xlfn.XLOOKUP(_xlfn.CONCAT($C7,$D7),$V:$V,Y:Y,"",0)) -> 55 | I7: =IF($C7="","",_xlfn.XLOOKUP(_xlfn.CONCAT($C7,$D7),$V:$V,Z:Z,"",0)) -> 7 | J7: =IF($C7="","",_xlfn.XLOOKUP(_xlfn.CONCAT($C7,$D7),$V:$V,AA:AA,"",0)) -> 포함 | K7: =IF($C7="","",_xlfn.XLOOKUP(_xlfn.CONCAT($C7,$D7),$V:$V,AB:AB,"",0)) -> 포함 | L7: =IF($C7="","",_xlfn.XLOOKUP(_xlfn.CONCAT($C7,$D7),$V:$V,AC:AC,"",0)) -> 8 | M7: {=_xlfn.LET(_xlpm.퇴실일, _xlfn.XLOOKUP(_xlfn.CONCAT(C7,D7),■퇴실정보!$B$4:$B$1000&■퇴실정보!$C$4:$C$1000,■퇴실정보!$E$4:$E$1000,0,0,-1),IF(TODAY()-_xlpm.퇴실일>1000,"",TODAY()-_xlpm.퇴실일))} -> 24 | N7: {=IF($C7="","",_xlfn.XLOOKUP(_xlfn.CONCAT($C7,$D7),◆관리정보!$B:$B & ◆관리정보!$C:$C,◆관리정보!$J:$J))} -> 단기 | O7: 다존하우스 208 | Q7: 스타빌 | R7: 키4150종 | V7: 제이앤제이101 | Y7: 75 | AD7: 사무실
A8: =IF($C8="","",_xlfn.XLOOKUP(_xlfn.CONCAT($C8,$D8),$V:$V,T:T,"",0)) | B8: =IF($C8="","",_xlfn.XLOOKUP(_xlfn.CONCAT($C8,$D8),$V:$V,U:U,"",0)) -> 10 | C8: 다존하우스 | D8: 605 | E8: =IF(C8="","",_xlfn.XLOOKUP(C8,$Q$6:$Q$100,$R$6:$R$100,"",0)) -> 731024# | F8: =IF($C8="","",_xlfn.XLOOKUP(_xlfn.CONCAT($C8,$D8),$V:$V,W:W,"",0)) -> 50 | G8: =IF($C8="","",_xlfn.XLOOKUP(_xlfn.CONCAT($C8,$D8),$V:$V,X:X,"",0)) -> 50 | H8: =IF($C8="","",_xlfn.XLOOKUP(_xlfn.CONCAT($C8,$D8),$V:$V,Y:Y,"",0)) -> 50 | I8: =IF($C8="","",_xlfn.XLOOKUP(_xlfn.CONCAT($C8,$D8),$V:$V,Z:Z,"",0)) -> 7 | J8: =IF($C8="","",_xlfn.XLOOKUP(_xlfn.CONCAT($C8,$D8),$V:$V,AA:AA,"",0)) -> 포함 | K8: =IF($C8="","",_xlfn.XLOOKUP(_xlfn.CONCAT($C8,$D8),$V:$V,AB:AB,"",0)) -> 포함 | L8: =IF($C8="","",_xlfn.XLOOKUP(_xlfn.CONCAT($C8,$D8),$V:$V,AC:AC,"",0)) -> 8 | M8: {=_xlfn.LET(_xlpm.퇴실일, _xlfn.XLOOKUP(_xlfn.CONCAT(C8,D8),■퇴실정보!$B$4:$B$1000&■퇴실정보!$C$4:$C$1000,■퇴실정보!$E$4:$E$1000,0,0,-1),IF(TODAY()-_xlpm.퇴실일>1000,"",TODAY()-_xlpm.퇴실일))} -> 3 | N8: {=IF($C8="","",_xlfn.XLOOKUP(_xlfn.CONCAT($C8,$D8),◆관리정보!$B:$B & ◆관리정보!$C:$C,◆관리정보!$J:$J))} -> 단기 | O8: 미래홈 102 | Q8: 아페이론 | R8: 경비키4150종 | U8: 15 | V8: 제이앤제이201 | W8: 165 | X8: 165 | Y8: 160 | Z8: 12 | AA8: 2.5 | AB8: 2.5 | AC8: 20 | AD8: 세미분리
A9: =IF($C9="","",_xlfn.XLOOKUP(_xlfn.CONCAT($C9,$D9),$V:$V,T:T,"",0)) | B9: =IF($C9="","",_xlfn.XLOOKUP(_xlfn.CONCAT($C9,$D9),$V:$V,U:U,"",0)) -> 11 | C9: 미래홈 | D9: 203 | E9: =IF(C9="","",_xlfn.XLOOKUP(C9,$Q$6:$Q$100,$R$6:$R$100,"",0)) -> #4150# | F9: =IF($C9="","",_xlfn.XLOOKUP(_xlfn.CONCAT($C9,$D9),$V:$V,W:W,"",0)) -> 70 | G9: =IF($C9="","",_xlfn.XLOOKUP(_xlfn.CONCAT($C9,$D9),$V:$V,X:X,"",0)) -> 50 | H9: =IF($C9="","",_xlfn.XLOOKUP(_xlfn.CONCAT($C9,$D9),$V:$V,Y:Y,"",0)) -> 50 | I9: =IF($C9="","",_xlfn.XLOOKUP(_xlfn.CONCAT($C9,$D9),$V:$V,Z:Z,"",0)) -> 7 | J9: =IF($C9="","",_xlfn.XLOOKUP(_xlfn.CONCAT($C9,$D9),$V:$V,AA:AA,"",0)) -> 포함 | K9: =IF($C9="","",_xlfn.XLOOKUP(_xlfn.CONCAT($C9,$D9),$V:$V,AB:AB,"",0)) -> 포함 | L9: =IF($C9="","",_xlfn.XLOOKUP(_xlfn.CONCAT($C9,$D9),$V:$V,AC:AC,"",0)) -> 10 | M9: {=_xlfn.LET(_xlpm.퇴실일, _xlfn.XLOOKUP(_xlfn.CONCAT(C9,D9),■퇴실정보!$B$4:$B$1000&■퇴실정보!$C$4:$C$1000,■퇴실정보!$E$4:$E$1000,0,0,-1),IF(TODAY()-_xlpm.퇴실일>1000,"",TODAY()-_xlpm.퇴실일))} -> 13 | N9: {=IF($C9="","",_xlfn.XLOOKUP(_xlfn.CONCAT($C9,$D9),◆관리정보!$B:$B & ◆관리정보!$C:$C,◆관리정보!$J:$J))} -> 단기 | O9: 미래홈 107 | Q9: 다존하우스 | R9: 731024# | U9: 20 | V9: 제이앤제이301 | W9: 165 | X9: 165 | Y9: 160 | Z9: 12 | AA9: 2.5 | AB9: 2.5 | AC9: 20 | AD9: 세미분리
A10: =IF($C10="","",_xlfn.XLOOKUP(_xlfn.CONCAT($C10,$D10),$V:$V,T:T,"",0)) | B10: =IF($C10="","",_xlfn.XLOOKUP(_xlfn.CONCAT($C10,$D10),$V:$V,U:U,"",0)) -> 15 | C10: 굿모닝빌 | D10: 203 | E10: =IF(C10="","",_xlfn.XLOOKUP(C10,$Q$6:$Q$100,$R$6:$R$100,"",0)) -> OPEN | F10: =IF($C10="","",_xlfn.XLOOKUP(_xlfn.CONCAT($C10,$D10),$V:$V,W:W,"",0)) -> 120 | G10: =IF($C10="","",_xlfn.XLOOKUP(_xlfn.CONCAT($C10,$D10),$V:$V,X:X,"",0)) -> 115 | H10: =IF($C10="","",_xlfn.XLOOKUP(_xlfn.CONCAT($C10,$D10),$V:$V,Y:Y,"",0)) -> 110 | I10: =IF($C10="","",_xlfn.XLOOKUP(_xlfn.CONCAT($C10,$D10),$V:$V,Z:Z,"",0)) -> 8 | J10: =IF($C10="","",_xlfn.XLOOKUP(_xlfn.CONCAT($C10,$D10),$V:$V,AA:AA,"",0)) -> 2.5 | K10: =IF($C10="","",_xlfn.XLOOKUP(_xlfn.CONCAT($C10,$D10),$V:$V,AB:AB,"",0)) -> 2.5 | L10: =IF($C10="","",_xlfn.XLOOKUP(_xlfn.CONCAT($C10,$D10),$V:$V,AC:AC,"",0)) -> 18 | M10: {=_xlfn.LET(_xlpm.퇴실일, _xlfn.XLOOKUP(_xlfn.CONCAT(C10,D10),■퇴실정보!$B$4:$B$1000&■퇴실정보!$C$4:$C$1000,■퇴실정보!$E$4:$E$1000,0,0,-1),IF(TODAY()-_xlpm.퇴실일>1000,"",TODAY()-_xlpm.퇴실일))} -> 20 | N10: {=IF($C10="","",_xlfn.XLOOKUP(_xlfn.CONCAT($C10,$D10),◆관리정보!$B:$B & ◆관리정보!$C:$C,◆관리정보!$J:$J))} -> 단기 | O10: 굿모닝빌 301 | Q10: 미래홈 | R10: #4150# | U10: 25 | V10: 제이앤제이401 | W10: 200 | X10: 200 | Y10: 195 | Z10: 15 | AA10: 3 | AB10: 2.5 | AC10: 20 | AD10: 복층투룸
A11: =IF($C11="","",_xlfn.XLOOKUP(_xlfn.CONCAT($C11,$D11),$V:$V,T:T,"",0)) | B11: =IF($C11="","",_xlfn.XLOOKUP(_xlfn.CONCAT($C11,$D11),$V:$V,U:U,"",0)) -> 15 | C11: 와이원빈티지 | D11: 202 | E11: =IF(C11="","",_xlfn.XLOOKUP(C11,$Q$6:$Q$100,$R$6:$R$100,"",0)) -> 종3435 | F11: =IF($C11="","",_xlfn.XLOOKUP(_xlfn.CONCAT($C11,$D11),$V:$V,W:W,"",0)) -> 110 | G11: =IF($C11="","",_xlfn.XLOOKUP(_xlfn.CONCAT($C11,$D11),$V:$V,X:X,"",0)) -> 105 | H11: =IF($C11="","",_xlfn.XLOOKUP(_xlfn.CONCAT($C11,$D11),$V:$V,Y:Y,"",0)) -> 100 | I11: =IF($C11="","",_xlfn.XLOOKUP(_xlfn.CONCAT($C11,$D11),$V:$V,Z:Z,"",0)) -> 8 | J11: =IF($C11="","",_xlfn.XLOOKUP(_xlfn.CONCAT($C11,$D11),$V:$V,AA:AA,"",0)) -> 2.5 | K11: =IF($C11="","",_xlfn.XLOOKUP(_xlfn.CONCAT($C11,$D11),$V:$V,AB:AB,"",0)) -> 2.5 | L11: =IF($C11="","",_xlfn.XLOOKUP(_xlfn.CONCAT($C11,$D11),$V:$V,AC:AC,"",0)) -> 18 | M11: {=_xlfn.LET(_xlpm.퇴실일, _xlfn.XLOOKUP(_xlfn.CONCAT(C11,D11),■퇴실정보!$B$4:$B$1000&■퇴실정보!$C$4:$C$1000,■퇴실정보!$E$4:$E$1000,0,0,-1),IF(TODAY()-_xlpm.퇴실일>1000,"",TODAY()-_xlpm.퇴실일))} -> 8 | N11: {=IF($C11="","",_xlfn.XLOOKUP(_xlfn.CONCAT($C11,$D11),◆관리정보!$B:$B & ◆관리정보!$C:$C,◆관리정보!$J:$J))} -> 단기 | O11: 굿모닝빌 402 | Q11: 포유빌 | R11: 키4150종 | U11: 10 | V11: 스타빌101 | W11: 70 | X11: 70 | Y11: 65 | Z11: 8 | AA11: 2.5 | AB11: 2.5 | AC11: 10 | AD11: 원룸
A12: =IF($C12="","",_xlfn.XLOOKUP(_xlfn.CONCAT($C12,$D12),$V:$V,T:T,"",0)) | B12: =IF($C12="","",_xlfn.XLOOKUP(_xlfn.CONCAT($C12,$D12),$V:$V,U:U,"",0)) -> 15 | C12: 와이원빈티지 | D12: 303 | E12: =IF(C12="","",_xlfn.XLOOKUP(C12,$Q$6:$Q$100,$R$6:$R$100,"",0)) -> 종3435 | F12: =IF($C12="","",_xlfn.XLOOKUP(_xlfn.CONCAT($C12,$D12),$V:$V,W:W,"",0)) -> 110 | G12: =IF($C12="","",_xlfn.XLOOKUP(_xlfn.CONCAT($C12,$D12),$V:$V,X:X,"",0)) -> 105 | H12: =IF($C12="","",_xlfn.XLOOKUP(_xlfn.CONCAT($C12,$D12),$V:$V,Y:Y,"",0)) -> 100 | I12: =IF($C12="","",_xlfn.XLOOKUP(_xlfn.CONCAT($C12,$D12),$V:$V,Z:Z,"",0)) -> 8 | J12: =IF($C12="","",_xlfn.XLOOKUP(_xlfn.CONCAT($C12,$D12),$V:$V,AA:AA,"",0)) -> 2.5 | K12: =IF($C12="","",_xlfn.XLOOKUP(_xlfn.CONCAT($C12,$D12),$V:$V,AB:AB,"",0)) -> 2.5 | L12: =IF($C12="","",_xlfn.XLOOKUP(_xlfn.CONCAT($C12,$D12),$V:$V,AC:AC,"",0)) -> 18 | M12: {=_xlfn.LET(_xlpm.퇴실일, _xlfn.XLOOKUP(_xlfn.CONCAT(C12,D12),■퇴실정보!$B$4:$B$1000&■퇴실정보!$C$4:$C$1000,■퇴실정보!$E$4:$E$1000,0,0,-1),IF(TODAY()-_xlpm.퇴실일>1000,"",TODAY()-_xlpm.퇴실일))} -> 46 | N12: {=IF($C12="","",_xlfn.XLOOKUP(_xlfn.CONCAT($C12,$D12),◆관리정보!$B:$B & ◆관리정보!$C:$C,◆관리정보!$J:$J))} -> 단기 | O12: 모던하우스 501 | Q12: W하우스 | R12: #4150# | U12: 10 | V12: 스타빌102 | W12: 70 | X12: 70 | Y12: 65 | Z12: 8 | AA12: 2.5 | AB12: 2.5 | AC12: 10 | AD12: 원룸
A13: =IF($C13="","",_xlfn.XLOOKUP(_xlfn.CONCAT($C13,$D13),$V:$V,T:T,"",0)) | B13: =IF($C13="","",_xlfn.XLOOKUP(_xlfn.CONCAT($C13,$D13),$V:$V,U:U,"",0)) -> 15 | C13: 모던하우스 | D13: 405 | E13: =IF(C13="","",_xlfn.XLOOKUP(C13,$Q$6:$Q$100,$R$6:$R$100,"",0)) -> #3754# | F13: =IF($C13="","",_xlfn.XLOOKUP(_xlfn.CONCAT($C13,$D13),$V:$V,W:W,"",0)) -> 125 | G13: =IF($C13="","",_xlfn.XLOOKUP(_xlfn.CONCAT($C13,$D13),$V:$V,X:X,"",0)) -> 125 | H13: =IF($C13="","",_xlfn.XLOOKUP(_xlfn.CONCAT($C13,$D13),$V:$V,Y:Y,"",0)) -> 120 | I13: =IF($C13="","",_xlfn.XLOOKUP(_xlfn.CONCAT($C13,$D13),$V:$V,Z:Z,"",0)) -> 8 | J13: =IF($C13="","",_xlfn.XLOOKUP(_xlfn.CONCAT($C13,$D13),$V:$V,AA:AA,"",0)) -> 2.5 | K13: =IF($C13="","",_xlfn.XLOOKUP(_xlfn.CONCAT($C13,$D13),$V:$V,AB:AB,"",0)) -> 2.5 | L13: =IF($C13="","",_xlfn.XLOOKUP(_xlfn.CONCAT($C13,$D13),$V:$V,AC:AC,"",0)) -> 20 | M13: {=_xlfn.LET(_xlpm.퇴실일, _xlfn.XLOOKUP(_xlfn.CONCAT(C13,D13),■퇴실정보!$B$4:$B$1000&■퇴실정보!$C$4:$C$1000,■퇴실정보!$E$4:$E$1000,0,0,-1),IF(TODAY()-_xlpm.퇴실일>1000,"",TODAY()-_xlpm.퇴실일))} -> 21 | N13: {=IF($C13="","",_xlfn.XLOOKUP(_xlfn.CONCAT($C13,$D13),◆관리정보!$B:$B & ◆관리정보!$C:$C,◆관리정보!$J:$J))} -> 단기 | O13: 제이드하우스 103 | Q13: 풍림빌딩 | R13: OPEN | U13: 10 | V13: 스타빌103 | W13: 70 | X13: 70 | Y13: 65 | Z13: 8 | AA13: 2.5 | AB13: 2.5 | AC13: 10 | AD13: 원룸
A14: =IF($C14="","",_xlfn.XLOOKUP(_xlfn.CONCAT($C14,$D14),$V:$V,T:T,"",0)) | B14: =IF($C14="","",_xlfn.XLOOKUP(_xlfn.CONCAT($C14,$D14),$V:$V,U:U,"",0)) -> 20 | C14: 모던라이프 | D14: 301 | E14: =IF(C14="","",_xlfn.XLOOKUP(C14,$Q$6:$Q$100,$R$6:$R$100,"",0)) -> 종6819 | F14: =IF($C14="","",_xlfn.XLOOKUP(_xlfn.CONCAT($C14,$D14),$V:$V,W:W,"",0)) -> 185 | G14: =IF($C14="","",_xlfn.XLOOKUP(_xlfn.CONCAT($C14,$D14),$V:$V,X:X,"",0)) -> 185 | H14: =IF($C14="","",_xlfn.XLOOKUP(_xlfn.CONCAT($C14,$D14),$V:$V,Y:Y,"",0)) -> 180 | I14: =IF($C14="","",_xlfn.XLOOKUP(_xlfn.CONCAT($C14,$D14),$V:$V,Z:Z,"",0)) -> 10 | J14: =IF($C14="","",_xlfn.XLOOKUP(_xlfn.CONCAT($C14,$D14),$V:$V,AA:AA,"",0)) -> 3 | K14: =IF($C14="","",_xlfn.XLOOKUP(_xlfn.CONCAT($C14,$D14),$V:$V,AB:AB,"",0)) -> 2.5 | L14: =IF($C14="","",_xlfn.XLOOKUP(_xlfn.CONCAT($C14,$D14),$V:$V,AC:AC,"",0)) -> 25 | M14: {=_xlfn.LET(_xlpm.퇴실일, _xlfn.XLOOKUP(_xlfn.CONCAT(C14,D14),■퇴실정보!$B$4:$B$1000&■퇴실정보!$C$4:$C$1000,■퇴실정보!$E$4:$E$1000,0,0,-1),IF(TODAY()-_xlpm.퇴실일>1000,"",TODAY()-_xlpm.퇴실일))} -> 6 | N14: {=IF($C14="","",_xlfn.XLOOKUP(_xlfn.CONCAT($C14,$D14),◆관리정보!$B:$B & ◆관리정보!$C:$C,◆관리정보!$J:$J))} -> 단기 | Q14: 모던하우스 | R14: #3754# | U14: 10 | V14: 스타빌105 | W14: 70 | X14: 70 | Y14: 65 | Z14: 8 | AA14: 2.5 | AB14: 2.5 | AC14: 10 | AD14: 원룸
A15: =IF($C15="","",_xlfn.XLOOKUP(_xlfn.CONCAT($C15,$D15),$V:$V,T:T,"",0)) | B15: =IF($C15="","",_xlfn.XLOOKUP(_xlfn.CONCAT($C15,$D15),$V:$V,U:U,"",0)) -> 20 | C15: 모던라이프 | D15: 303 | E15: =IF(C15="","",_xlfn.XLOOKUP(C15,$Q$6:$Q$100,$R$6:$R$100,"",0)) -> 종6819 | F15: =IF($C15="","",_xlfn.XLOOKUP(_xlfn.CONCAT($C15,$D15),$V:$V,W:W,"",0)) -> 175 | G15: =IF($C15="","",_xlfn.XLOOKUP(_xlfn.CONCAT($C15,$D15),$V:$V,X:X,"",0)) -> 175 | H15: =IF($C15="","",_xlfn.XLOOKUP(_xlfn.CONCAT($C15,$D15),$V:$V,Y:Y,"",0)) -> 175 | I15: =IF($C15="","",_xlfn.XLOOKUP(_xlfn.CONCAT($C15,$D15),$V:$V,Z:Z,"",0)) -> 10 | J15: =IF($C15="","",_xlfn.XLOOKUP(_xlfn.CONCAT($C15,$D15),$V:$V,AA:AA,"",0)) -> 3 | K15: =IF($C15="","",_xlfn.XLOOKUP(_xlfn.CONCAT($C15,$D15),$V:$V,AB:AB,"",0)) -> 2.5 | L15: =IF($C15="","",_xlfn.XLOOKUP(_xlfn.CONCAT($C15,$D15),$V:$V,AC:AC,"",0)) -> 25 | M15: {=_xlfn.LET(_xlpm.퇴실일, _xlfn.XLOOKUP(_xlfn.CONCAT(C15,D15),■퇴실정보!$B$4:$B$1000&■퇴실정보!$C$4:$C$1000,■퇴실정보!$E$4:$E$1000,0,0,-1),IF(TODAY()-_xlpm.퇴실일>1000,"",TODAY()-_xlpm.퇴실일))} -> 58 | N15: {=IF($C15="","",_xlfn.XLOOKUP(_xlfn.CONCAT($C15,$D15),◆관리정보!$B:$B & ◆관리정보!$C:$C,◆관리정보!$J:$J))} -> 단기 | Q15: 모던라이프 | R15: 종6819 | U15: 10 | V15: 스타빌201 | W15: 75 | X15: 75 | Y15: 70 | Z15: 8 | AA15: 2.5 | AB15: 2.5 | AC15: 10 | AD15: 원룸
A16: =IF($C16="","",_xlfn.XLOOKUP(_xlfn.CONCAT($C16,$D16),$V:$V,T:T,"",0)) | B16: =IF($C16="","",_xlfn.XLOOKUP(_xlfn.CONCAT($C16,$D16),$V:$V,U:U,"",0)) -> 0.6 | C16: 우영빌딩 | D16: 2층 | E16: =IF(C16="","",_xlfn.XLOOKUP(C16,$Q$6:$Q$100,$R$6:$R$100,"",0)) -> 1104 | F16: =IF($C16="","",_xlfn.XLOOKUP(_xlfn.CONCAT($C16,$D16),$V:$V,W:W,"",0)) -> 10000 | G16: =IF($C16="","",_xlfn.XLOOKUP(_xlfn.CONCAT($C16,$D16),$V:$V,X:X,"",0)) -> 550 | H16: =IF($C16="","",_xlfn.XLOOKUP(_xlfn.CONCAT($C16,$D16),$V:$V,Y:Y,"",0)) -> 550 | I16: =IF($C16="","",_xlfn.XLOOKUP(_xlfn.CONCAT($C16,$D16),$V:$V,Z:Z,"",0)) -> 100 | J16: =IF($C16="","",_xlfn.XLOOKUP(_xlfn.CONCAT($C16,$D16),$V:$V,AA:AA,"",0)) -> 별도 | K16: =IF($C16="","",_xlfn.XLOOKUP(_xlfn.CONCAT($C16,$D16),$V:$V,AB:AB,"",0)) | L16: =IF($C16="","",_xlfn.XLOOKUP(_xlfn.CONCAT($C16,$D16),$V:$V,AC:AC,"",0)) | M16: {=_xlfn.LET(_xlpm.퇴실일, _xlfn.XLOOKUP(_xlfn.CONCAT(C16,D16),■퇴실정보!$B$4:$B$1000&■퇴실정보!$C$4:$C$1000,■퇴실정보!$E$4:$E$1000,0,0,-1),IF(TODAY()-_xlpm.퇴실일>1000,"",TODAY()-_xlpm.퇴실일))} | N16: {=IF($C16="","",_xlfn.XLOOKUP(_xlfn.CONCAT($C16,$D16),◆관리정보!$B:$B & ◆관리정보!$C:$C,◆관리정보!$J:$J))} -> 일반 | Q16: 리트코하우스 | R16: 종3435 | U16: 10 | V16: 스타빌202 | W16: 75 | X16: 75 | Y16: 70 | Z16: 8 | AA16: 2.5 | AB16: 2.5 | AC16: 10 | AD16: 원룸
A17: =IF($C17="","",_xlfn.XLOOKUP(_xlfn.CONCAT($C17,$D17),$V:$V,T:T,"",0)) | B17: =IF($C17="","",_xlfn.XLOOKUP(_xlfn.CONCAT($C17,$D17),$V:$V,U:U,"",0)) -> 0.6 | C17: 우영빌딩 | D17: 4층 | E17: =IF(C17="","",_xlfn.XLOOKUP(C17,$Q$6:$Q$100,$R$6:$R$100,"",0)) -> 1104 | F17: =IF($C17="","",_xlfn.XLOOKUP(_xlfn.CONCAT($C17,$D17),$V:$V,W:W,"",0)) -> 7000 | G17: =IF($C17="","",_xlfn.XLOOKUP(_xlfn.CONCAT($C17,$D17),$V:$V,X:X,"",0)) -> 320 | H17: =IF($C17="","",_xlfn.XLOOKUP(_xlfn.CONCAT($C17,$D17),$V:$V,Y:Y,"",0)) -> 320 | I17: =IF($C17="","",_xlfn.XLOOKUP(_xlfn.CONCAT($C17,$D17),$V:$V,Z:Z,"",0)) -> 50 | J17: =IF($C17="","",_xlfn.XLOOKUP(_xlfn.CONCAT($C17,$D17),$V:$V,AA:AA,"",0)) -> 별도 | K17: =IF($C17="","",_xlfn.XLOOKUP(_xlfn.CONCAT($C17,$D17),$V:$V,AB:AB,"",0)) | L17: =IF($C17="","",_xlfn.XLOOKUP(_xlfn.CONCAT($C17,$D17),$V:$V,AC:AC,"",0)) | M17: {=_xlfn.LET(_xlpm.퇴실일, _xlfn.XLOOKUP(_xlfn.CONCAT(C17,D17),■퇴실정보!$B$4:$B$1000&■퇴실정보!$C$4:$C$1000,■퇴실정보!$E$4:$E$1000,0,0,-1),IF(TODAY()-_xlpm.퇴실일>1000,"",TODAY()-_xlpm.퇴실일))} | N17: {=IF($C17="","",_xlfn.XLOOKUP(_xlfn.CONCAT($C17,$D17),◆관리정보!$B:$B & ◆관리정보!$C:$C,◆관리정보!$J:$J))} -> 일반 | Q17: 와이원빈티지 | R17: 종3435 | U17: 10 | V17: 스타빌203 | W17: 75 | X17: 75 | Y17: 70 | Z17: 8 | AA17: 2.5 | AB17: 2.5 | AC17: 10 | AD17: 원룸
A18: =IF($C18="","",_xlfn.XLOOKUP(_xlfn.CONCAT($C18,$D18),$V:$V,T:T,"",0)) | B18: =IF($C18="","",_xlfn.XLOOKUP(_xlfn.CONCAT($C18,$D18),$V:$V,U:U,"",0)) -> 0.6 | C18: 문화빌딩 | D18: B01 | E18: =IF(C18="","",_xlfn.XLOOKUP(C18,$Q$6:$Q$100,$R$6:$R$100,"",0)) -> OPEN | F18: =IF($C18="","",_xlfn.XLOOKUP(_xlfn.CONCAT($C18,$D18),$V:$V,W:W,"",0)) -> 4000 | G18: =IF($C18="","",_xlfn.XLOOKUP(_xlfn.CONCAT($C18,$D18),$V:$V,X:X,"",0)) -> 330 | H18: =IF($C18="","",_xlfn.XLOOKUP(_xlfn.CONCAT($C18,$D18),$V:$V,Y:Y,"",0)) -> 330 | I18: =IF($C18="","",_xlfn.XLOOKUP(_xlfn.CONCAT($C18,$D18),$V:$V,Z:Z,"",0)) -> 40 | J18: =IF($C18="","",_xlfn.XLOOKUP(_xlfn.CONCAT($C18,$D18),$V:$V,AA:AA,"",0)) -> 별도 | K18: =IF($C18="","",_xlfn.XLOOKUP(_xlfn.CONCAT($C18,$D18),$V:$V,AB:AB,"",0)) | L18: =IF($C18="","",_xlfn.XLOOKUP(_xlfn.CONCAT($C18,$D18),$V:$V,AC:AC,"",0)) | M18: {=_xlfn.LET(_xlpm.퇴실일, _xlfn.XLOOKUP(_xlfn.CONCAT(C18,D18),■퇴실정보!$B$4:$B$1000&■퇴실정보!$C$4:$C$1000,■퇴실정보!$E$4:$E$1000,0,0,-1),IF(TODAY()-_xlpm.퇴실일>1000,"",TODAY()-_xlpm.퇴실일))} | N18: {=IF($C18="","",_xlfn.XLOOKUP(_xlfn.CONCAT($C18,$D18),◆관리정보!$B:$B & ◆관리정보!$C:$C,◆관리정보!$J:$J))} -> 상가 | Q18: 굿모닝빌 | R18: OPEN | U18: 10 | V18: 스타빌205 | W18: 75 | X18: 75 | Y18: 70 | Z18: 8 | AA18: 2.5 | AB18: 2.5 | AC18: 10 | AD18: 원룸
A19: =IF($C19="","",_xlfn.XLOOKUP(_xlfn.CONCAT($C19,$D19),$V:$V,T:T,"",0)) | B19: =IF($C19="","",_xlfn.XLOOKUP(_xlfn.CONCAT($C19,$D19),$V:$V,U:U,"",0)) -> 0.6 | C19: 문화빌딩 | D19: 2층 | E19: =IF(C19="","",_xlfn.XLOOKUP(C19,$Q$6:$Q$100,$R$6:$R$100,"",0)) -> OPEN | F19: =IF($C19="","",_xlfn.XLOOKUP(_xlfn.CONCAT($C19,$D19),$V:$V,W:W,"",0)) -> 12000 | G19: =IF($C19="","",_xlfn.XLOOKUP(_xlfn.CONCAT($C19,$D19),$V:$V,X:X,"",0)) -> 650 | H19: =IF($C19="","",_xlfn.XLOOKUP(_xlfn.CONCAT($C19,$D19),$V:$V,Y:Y,"",0)) -> 650 | I19: =IF($C19="","",_xlfn.XLOOKUP(_xlfn.CONCAT($C19,$D19),$V:$V,Z:Z,"",0)) -> 40 | J19: =IF($C19="","",_xlfn.XLOOKUP(_xlfn.CONCAT($C19,$D19),$V:$V,AA:AA,"",0)) -> 별도 | K19: =IF($C19="","",_xlfn.XLOOKUP(_xlfn.CONCAT($C19,$D19),$V:$V,AB:AB,"",0)) | L19: =IF($C19="","",_xlfn.XLOOKUP(_xlfn.CONCAT($C19,$D19),$V:$V,AC:AC,"",0)) | M19: {=_xlfn.LET(_xlpm.퇴실일, _xlfn.XLOOKUP(_xlfn.CONCAT(C19,D19),■퇴실정보!$B$4:$B$1000&■퇴실정보!$C$4:$C$1000,■퇴실정보!$E$4:$E$1000,0,0,-1),IF(TODAY()-_xlpm.퇴실일>1000,"",TODAY()-_xlpm.퇴실일))} | N19: {=IF($C19="","",_xlfn.XLOOKUP(_xlfn.CONCAT($C19,$D19),◆관리정보!$B:$B & ◆관리정보!$C:$C,◆관리정보!$J:$J))} -> 상가 | Q19: 모닝빌 | R19: 작은 문 OPEN | U19: 10 | V19: 스타빌301 | W19: 75 | X19: 75 | Y19: 70 | Z19: 8 | AA19: 2.5 | AB19: 2.5 | AC19: 10 | AD19: 원룸
A20: =IF($C20="","",_xlfn.XLOOKUP(_xlfn.CONCAT($C20,$D20),$V:$V,T:T,"",0)) | B20: =IF($C20="","",_xlfn.XLOOKUP(_xlfn.CONCAT($C20,$D20),$V:$V,U:U,"",0)) -> 0.9 | C20: 어반그레이 | D20: B01 | E20: =IF(C20="","",_xlfn.XLOOKUP(C20,$Q$6:$Q$100,$R$6:$R$100,"",0)) -> 4150 | F20: =IF($C20="","",_xlfn.XLOOKUP(_xlfn.CONCAT($C20,$D20),$V:$V,W:W,"",0)) -> 6000 | G20: =IF($C20="","",_xlfn.XLOOKUP(_xlfn.CONCAT($C20,$D20),$V:$V,X:X,"",0)) -> 400 | H20: =IF($C20="","",_xlfn.XLOOKUP(_xlfn.CONCAT($C20,$D20),$V:$V,Y:Y,"",0)) -> 400 | I20: =IF($C20="","",_xlfn.XLOOKUP(_xlfn.CONCAT($C20,$D20),$V:$V,Z:Z,"",0)) -> 50 | J20: =IF($C20="","",_xlfn.XLOOKUP(_xlfn.CONCAT($C20,$D20),$V:$V,AA:AA,"",0)) | K20: =IF($C20="","",_xlfn.XLOOKUP(_xlfn.CONCAT($C20,$D20),$V:$V,AB:AB,"",0)) | L20: =IF($C20="","",_xlfn.XLOOKUP(_xlfn.CONCAT($C20,$D20),$V:$V,AC:AC,"",0)) | M20: {=_xlfn.LET(_xlpm.퇴실일, _xlfn.XLOOKUP(_xlfn.CONCAT(C20,D20),■퇴실정보!$B$4:$B$1000&■퇴실정보!$C$4:$C$1000,■퇴실정보!$E$4:$E$1000,0,0,-1),IF(TODAY()-_xlpm.퇴실일>1000,"",TODAY()-_xlpm.퇴실일))} | N20: {=IF($C20="","",_xlfn.XLOOKUP(_xlfn.CONCAT($C20,$D20),◆관리정보!$B:$B & ◆관리정보!$C:$C,◆관리정보!$J:$J))} -> 상가 | Q20: 에덴빌 | R20: #1202# | U20: 10 | V20: 스타빌302 | W20: 75 | X20: 75 | Y20: 70 | Z20: 8 | AA20: 2.5 | AB20: 2.5 | AC20: 10 | AD20: 원룸
A21: =IF($C21="","",_xlfn.XLOOKUP(_xlfn.CONCAT($C21,$D21),$V:$V,T:T,"",0)) | B21: =IF($C21="","",_xlfn.XLOOKUP(_xlfn.CONCAT($C21,$D21),$V:$V,U:U,"",0)) -> 0.9 | C21: 어반그레이 | D21: 1층 | E21: =IF(C21="","",_xlfn.XLOOKUP(C21,$Q$6:$Q$100,$R$6:$R$100,"",0)) -> 4150 | F21: =IF($C21="","",_xlfn.XLOOKUP(_xlfn.CONCAT($C21,$D21),$V:$V,W:W,"",0)) -> 7000 | G21: =IF($C21="","",_xlfn.XLOOKUP(_xlfn.CONCAT($C21,$D21),$V:$V,X:X,"",0)) -> 490 | H21: =IF($C21="","",_xlfn.XLOOKUP(_xlfn.CONCAT($C21,$D21),$V:$V,Y:Y,"",0)) -> 490 | I21: =IF($C21="","",_xlfn.XLOOKUP(_xlfn.CONCAT($C21,$D21),$V:$V,Z:Z,"",0)) -> 50 | J21: =IF($C21="","",_xlfn.XLOOKUP(_xlfn.CONCAT($C21,$D21),$V:$V,AA:AA,"",0)) | K21: =IF($C21="","",_xlfn.XLOOKUP(_xlfn.CONCAT($C21,$D21),$V:$V,AB:AB,"",0)) | L21: =IF($C21="","",_xlfn.XLOOKUP(_xlfn.CONCAT($C21,$D21),$V:$V,AC:AC,"",0)) | M21: {=_xlfn.LET(_xlpm.퇴실일, _xlfn.XLOOKUP(_xlfn.CONCAT(C21,D21),■퇴실정보!$B$4:$B$1000&■퇴실정보!$C$4:$C$1000,■퇴실정보!$E$4:$E$1000,0,0,-1),IF(TODAY()-_xlpm.퇴실일>1000,"",TODAY()-_xlpm.퇴실일))} | N21: {=IF($C21="","",_xlfn.XLOOKUP(_xlfn.CONCAT($C21,$D21),◆관리정보!$B:$B & ◆관리정보!$C:$C,◆관리정보!$J:$J))} -> 상가 | Q21: 한스텔 | R21: OPEN | U21: 10 | V21: 스타빌303 | W21: 75 | X21: 75 | Y21: 70 | Z21: 8 | AA21: 2.5 | AB21: 2.5 | AC21: 10 | AD21: 원룸
A22: =IF($C22="","",_xlfn.XLOOKUP(_xlfn.CONCAT($C22,$D22),$V:$V,T:T,"",0)) | B22: =IF($C22="","",_xlfn.XLOOKUP(_xlfn.CONCAT($C22,$D22),$V:$V,U:U,"",0)) -> 0.9 | C22: 어반그레이 | D22: 2층 | E22: =IF(C22="","",_xlfn.XLOOKUP(C22,$Q$6:$Q$100,$R$6:$R$100,"",0)) -> 4150 | F22: =IF($C22="","",_xlfn.XLOOKUP(_xlfn.CONCAT($C22,$D22),$V:$V,W:W,"",0)) -> 5000 | G22: =IF($C22="","",_xlfn.XLOOKUP(_xlfn.CONCAT($C22,$D22),$V:$V,X:X,"",0)) -> 360 | H22: =IF($C22="","",_xlfn.XLOOKUP(_xlfn.CONCAT($C22,$D22),$V:$V,Y:Y,"",0)) -> 360 | I22: =IF($C22="","",_xlfn.XLOOKUP(_xlfn.CONCAT($C22,$D22),$V:$V,Z:Z,"",0)) -> 50 | J22: =IF($C22="","",_xlfn.XLOOKUP(_xlfn.CONCAT($C22,$D22),$V:$V,AA:AA,"",0)) | K22: =IF($C22="","",_xlfn.XLOOKUP(_xlfn.CONCAT($C22,$D22),$V:$V,AB:AB,"",0)) | L22: =IF($C22="","",_xlfn.XLOOKUP(_xlfn.CONCAT($C22,$D22),$V:$V,AC:AC,"",0)) | M22: {=_xlfn.LET(_xlpm.퇴실일, _xlfn.XLOOKUP(_xlfn.CONCAT(C22,D22),■퇴실정보!$B$4:$B$1000&■퇴실정보!$C$4:$C$1000,■퇴실정보!$E$4:$E$1000,0,0,-1),IF(TODAY()-_xlpm.퇴실일>1000,"",TODAY()-_xlpm.퇴실일))} | N22: {=IF($C22="","",_xlfn.XLOOKUP(_xlfn.CONCAT($C22,$D22),◆관리정보!$B:$B & ◆관리정보!$C:$C,◆관리정보!$J:$J))} -> 상가 | Q22: 지앤지2 | R22: 종-4150-종 | U22: 10 | V22: 스타빌305 | W22: 75 | X22: 75 | Y22: 70 | Z22: 8 | AA22: 2.5 | AB22: 2.5 | AC22: 10 | AD22: 원룸
A23: =IF($C23="","",_xlfn.XLOOKUP(_xlfn.CONCAT($C23,$D23),$V:$V,T:T,"",0)) -> 10 | B23: =IF($C23="","",_xlfn.XLOOKUP(_xlfn.CONCAT($C23,$D23),$V:$V,U:U,"",0)) -> 15 | C23: 제이드하우스 | D23: 202 | E23: =IF(C23="","",_xlfn.XLOOKUP(C23,$Q$6:$Q$100,$R$6:$R$100,"",0)) -> 종 5323 | F23: =IF($C23="","",_xlfn.XLOOKUP(_xlfn.CONCAT($C23,$D23),$V:$V,W:W,"",0)) -> 125 | G23: =IF($C23="","",_xlfn.XLOOKUP(_xlfn.CONCAT($C23,$D23),$V:$V,X:X,"",0)) -> 125 | H23: =IF($C23="","",_xlfn.XLOOKUP(_xlfn.CONCAT($C23,$D23),$V:$V,Y:Y,"",0)) -> 120 | I23: =IF($C23="","",_xlfn.XLOOKUP(_xlfn.CONCAT($C23,$D23),$V:$V,Z:Z,"",0)) -> 10 | J23: =IF($C23="","",_xlfn.XLOOKUP(_xlfn.CONCAT($C23,$D23),$V:$V,AA:AA,"",0)) -> 2.5 | K23: =IF($C23="","",_xlfn.XLOOKUP(_xlfn.CONCAT($C23,$D23),$V:$V,AB:AB,"",0)) -> 2.5 | L23: =IF($C23="","",_xlfn.XLOOKUP(_xlfn.CONCAT($C23,$D23),$V:$V,AC:AC,"",0)) -> 20 | M23: {=_xlfn.LET(_xlpm.퇴실일, _xlfn.XLOOKUP(_xlfn.CONCAT(C23,D23),■퇴실정보!$B$4:$B$1000&■퇴실정보!$C$4:$C$1000,■퇴실정보!$E$4:$E$1000,0,0,-1),IF(TODAY()-_xlpm.퇴실일>1000,"",TODAY()-_xlpm.퇴실일))} | N23: {=IF($C23="","",_xlfn.XLOOKUP(_xlfn.CONCAT($C23,$D23),◆관리정보!$B:$B & ◆관리정보!$C:$C,◆관리정보!$J:$J))} -> 0 | Q23: 토브미하우스 | R23: 4150 | U23: 10 | V23: 스타빌401 | W23: 75 | X23: 75 | Y23: 70 | Z23: 8 | AA23: 2.5 | AB23: 2.5 | AC23: 10 | AD23: 원룸
A24: =IF($C24="","",_xlfn.XLOOKUP(_xlfn.CONCAT($C24,$D24),$V:$V,T:T,"",0)) | B24: =IF($C24="","",_xlfn.XLOOKUP(_xlfn.CONCAT($C24,$D24),$V:$V,U:U,"",0)) -> 0.6 | C24: 상건빌딩 | D24: 301 | E24: =IF(C24="","",_xlfn.XLOOKUP(C24,$Q$6:$Q$100,$R$6:$R$100,"",0)) | F24: =IF($C24="","",_xlfn.XLOOKUP(_xlfn.CONCAT($C24,$D24),$V:$V,W:W,"",0)) -> 10000 | G24: =IF($C24="","",_xlfn.XLOOKUP(_xlfn.CONCAT($C24,$D24),$V:$V,X:X,"",0)) -> 650 | H24: =IF($C24="","",_xlfn.XLOOKUP(_xlfn.CONCAT($C24,$D24),$V:$V,Y:Y,"",0)) -> 650 | I24: =IF($C24="","",_xlfn.XLOOKUP(_xlfn.CONCAT($C24,$D24),$V:$V,Z:Z,"",0)) -> 80 | J24: =IF($C24="","",_xlfn.XLOOKUP(_xlfn.CONCAT($C24,$D24),$V:$V,AA:AA,"",0)) -> 별도 | K24: =IF($C24="","",_xlfn.XLOOKUP(_xlfn.CONCAT($C24,$D24),$V:$V,AB:AB,"",0)) | L24: =IF($C24="","",_xlfn.XLOOKUP(_xlfn.CONCAT($C24,$D24),$V:$V,AC:AC,"",0)) | M24: {=_xlfn.LET(_xlpm.퇴실일, _xlfn.XLOOKUP(_xlfn.CONCAT(C24,D24),■퇴실정보!$B$4:$B$1000&■퇴실정보!$C$4:$C$1000,■퇴실정보!$E$4:$E$1000,0,0,-1),IF(TODAY()-_xlpm.퇴실일>1000,"",TODAY()-_xlpm.퇴실일))} | N24: {=IF($C24="","",_xlfn.XLOOKUP(_xlfn.CONCAT($C24,$D24),◆관리정보!$B:$B & ◆관리정보!$C:$C,◆관리정보!$J:$J))} -> 일반 | Q24: 서우하우스 | R24: OPEN | U24: 10 | V24: 스타빌402 | W24: 75 | X24: 75 | Y24: 70 | Z24: 8 | AA24: 2.5 | AB24: 2.5 | AC24: 10 | AD24: 원룸
A25: =IF($C25="","",_xlfn.XLOOKUP(_xlfn.CONCAT($C25,$D25),$V:$V,T:T,"",0)) | B25: =IF($C25="","",_xlfn.XLOOKUP(_xlfn.CONCAT($C25,$D25),$V:$V,U:U,"",0)) -> 0.6 | C25: 상건빌딩 | D25: 302 | E25: =IF(C25="","",_xlfn.XLOOKUP(C25,$Q$6:$Q$100,$R$6:$R$100,"",0)) | F25: =IF($C25="","",_xlfn.XLOOKUP(_xlfn.CONCAT($C25,$D25),$V:$V,W:W,"",0)) -> 6000 | G25: =IF($C25="","",_xlfn.XLOOKUP(_xlfn.CONCAT($C25,$D25),$V:$V,X:X,"",0)) -> 500 | H25: =IF($C25="","",_xlfn.XLOOKUP(_xlfn.CONCAT($C25,$D25),$V:$V,Y:Y,"",0)) -> 500 | I25: =IF($C25="","",_xlfn.XLOOKUP(_xlfn.CONCAT($C25,$D25),$V:$V,Z:Z,"",0)) -> 80 | J25: =IF($C25="","",_xlfn.XLOOKUP(_xlfn.CONCAT($C25,$D25),$V:$V,AA:AA,"",0)) -> 별도 | K25: =IF($C25="","",_xlfn.XLOOKUP(_xlfn.CONCAT($C25,$D25),$V:$V,AB:AB,"",0)) | L25: =IF($C25="","",_xlfn.XLOOKUP(_xlfn.CONCAT($C25,$D25),$V:$V,AC:AC,"",0)) | M25: {=_xlfn.LET(_xlpm.퇴실일, _xlfn.XLOOKUP(_xlfn.CONCAT(C25,D25),■퇴실정보!$B$4:$B$1000&■퇴실정보!$C$4:$C$1000,■퇴실정보!$E$4:$E$1000,0,0,-1),IF(TODAY()-_xlpm.퇴실일>1000,"",TODAY()-_xlpm.퇴실일))} | N25: {=IF($C25="","",_xlfn.XLOOKUP(_xlfn.CONCAT($C25,$D25),◆관리정보!$B:$B & ◆관리정보!$C:$C,◆관리정보!$J:$J))} -> 일반 | Q25: 제이에스하우스 | R25: OPEN | U25: 10 | V25: 스타빌403 | W25: 75 | X25: 75 | Y25: 70 | Z25: 8 | AA25: 2.5 | AB25: 2.5 | AC25: 10 | AD25: 원룸
A26: =IF($C26="","",_xlfn.XLOOKUP(_xlfn.CONCAT($C26,$D26),$V:$V,T:T,"",0)) | B26: =IF($C26="","",_xlfn.XLOOKUP(_xlfn.CONCAT($C26,$D26),$V:$V,U:U,"",0)) -> 0.6 | C26: 미진빌딩 | D26: 5층 | E26: =IF(C26="","",_xlfn.XLOOKUP(C26,$Q$6:$Q$100,$R$6:$R$100,"",0)) | F26: =IF($C26="","",_xlfn.XLOOKUP(_xlfn.CONCAT($C26,$D26),$V:$V,W:W,"",0)) -> 10000 | G26: =IF($C26="","",_xlfn.XLOOKUP(_xlfn.CONCAT($C26,$D26),$V:$V,X:X,"",0)) -> 550 | H26: =IF($C26="","",_xlfn.XLOOKUP(_xlfn.CONCAT($C26,$D26),$V:$V,Y:Y,"",0)) -> 550 | I26: =IF($C26="","",_xlfn.XLOOKUP(_xlfn.CONCAT($C26,$D26),$V:$V,Z:Z,"",0)) -> 80 | J26: =IF($C26="","",_xlfn.XLOOKUP(_xlfn.CONCAT($C26,$D26),$V:$V,AA:AA,"",0)) | K26: =IF($C26="","",_xlfn.XLOOKUP(_xlfn.CONCAT($C26,$D26),$V:$V,AB:AB,"",0)) | L26: =IF($C26="","",_xlfn.XLOOKUP(_xlfn.CONCAT($C26,$D26),$V:$V,AC:AC,"",0)) | M26: {=_xlfn.LET(_xlpm.퇴실일, _xlfn.XLOOKUP(_xlfn.CONCAT(C26,D26),■퇴실정보!$B$4:$B$1000&■퇴실정보!$C$4:$C$1000,■퇴실정보!$E$4:$E$1000,0,0,-1),IF(TODAY()-_xlpm.퇴실일>1000,"",TODAY()-_xlpm.퇴실일))} | N26: {=IF($C26="","",_xlfn.XLOOKUP(_xlfn.CONCAT($C26,$D26),◆관리정보!$B:$B & ◆관리정보!$C:$C,◆관리정보!$J:$J))} -> 일반 | Q26: 우진빌딩 | R26: OPEN | U26: 10 | V26: 스타빌405 | W26: 75 | X26: 75 | Y26: 70 | Z26: 8 | AA26: 2.5 | AB26: 2.5 | AC26: 10 | AD26: 원룸
A27: =IF($C27="","",_xlfn.XLOOKUP(_xlfn.CONCAT($C27,$D27),$V:$V,T:T,"",0)) | B27: =IF($C27="","",_xlfn.XLOOKUP(_xlfn.CONCAT($C27,$D27),$V:$V,U:U,"",0)) -> 0.6 | C27: 유석빌딩 | D27: 402 | E27: =IF(C27="","",_xlfn.XLOOKUP(C27,$Q$6:$Q$100,$R$6:$R$100,"",0)) -> 1565* | F27: =IF($C27="","",_xlfn.XLOOKUP(_xlfn.CONCAT($C27,$D27),$V:$V,W:W,"",0)) -> 1000 | G27: =IF($C27="","",_xlfn.XLOOKUP(_xlfn.CONCAT($C27,$D27),$V:$V,X:X,"",0)) -> 50 | H27: =IF($C27="","",_xlfn.XLOOKUP(_xlfn.CONCAT($C27,$D27),$V:$V,Y:Y,"",0)) -> 50 | I27: =IF($C27="","",_xlfn.XLOOKUP(_xlfn.CONCAT($C27,$D27),$V:$V,Z:Z,"",0)) | J27: =IF($C27="","",_xlfn.XLOOKUP(_xlfn.CONCAT($C27,$D27),$V:$V,AA:AA,"",0)) -> 별도 | K27: =IF($C27="","",_xlfn.XLOOKUP(_xlfn.CONCAT($C27,$D27),$V:$V,AB:AB,"",0)) -> 별도 | L27: =IF($C27="","",_xlfn.XLOOKUP(_xlfn.CONCAT($C27,$D27),$V:$V,AC:AC,"",0)) | M27: {=_xlfn.LET(_xlpm.퇴실일, _xlfn.XLOOKUP(_xlfn.CONCAT(C27,D27),■퇴실정보!$B$4:$B$1000&■퇴실정보!$C$4:$C$1000,■퇴실정보!$E$4:$E$1000,0,0,-1),IF(TODAY()-_xlpm.퇴실일>1000,"",TODAY()-_xlpm.퇴실일))} | N27: {=IF($C27="","",_xlfn.XLOOKUP(_xlfn.CONCAT($C27,$D27),◆관리정보!$B:$B & ◆관리정보!$C:$C,◆관리정보!$J:$J))} -> 일반 | Q27: 우영빌딩 | R27: 1104 | U27: 20 | V27: 아페이론101 | W27: 125 | X27: 125 | Y27: 120 | Z27: 8 | AA27: 2.5 | AB27: 2.5 | AC27: 18 | AD27: 원룸
A28: =IF($C28="","",_xlfn.XLOOKUP(_xlfn.CONCAT($C28,$D28),$V:$V,T:T,"",0)) | B28: =IF($C28="","",_xlfn.XLOOKUP(_xlfn.CONCAT($C28,$D28),$V:$V,U:U,"",0)) | E28: =IF(C28="","",_xlfn.XLOOKUP(C28,$Q$6:$Q$100,$R$6:$R$100,"",0)) | F28: =IF($C28="","",_xlfn.XLOOKUP(_xlfn.CONCAT($C28,$D28),$V:$V,W:W,"",0)) | G28: =IF($C28="","",_xlfn.XLOOKUP(_xlfn.CONCAT($C28,$D28),$V:$V,X:X,"",0)) | H28: =IF($C28="","",_xlfn.XLOOKUP(_xlfn.CONCAT($C28,$D28),$V:$V,Y:Y,"",0)) | I28: =IF($C28="","",_xlfn.XLOOKUP(_xlfn.CONCAT($C28,$D28),$V:$V,Z:Z,"",0)) | J28: =IF($C28="","",_xlfn.XLOOKUP(_xlfn.CONCAT($C28,$D28),$V:$V,AA:AA,"",0)) | K28: =IF($C28="","",_xlfn.XLOOKUP(_xlfn.CONCAT($C28,$D28),$V:$V,AB:AB,"",0)) | L28: =IF($C28="","",_xlfn.XLOOKUP(_xlfn.CONCAT($C28,$D28),$V:$V,AC:AC,"",0)) | M28: {=_xlfn.LET(_xlpm.퇴실일, _xlfn.XLOOKUP(_xlfn.CONCAT(C28,D28),■퇴실정보!$B$4:$B$1000&■퇴실정보!$C$4:$C$1000,■퇴실정보!$E$4:$E$1000,0,0,-1),IF(TODAY()-_xlpm.퇴실일>1000,"",TODAY()-_xlpm.퇴실일))} | N28: {=IF($C28="","",_xlfn.XLOOKUP(_xlfn.CONCAT($C28,$D28),◆관리정보!$B:$B & ◆관리정보!$C:$C,◆관리정보!$J:$J))} | Q28: 메종빌 | R28: 종1024 | U28: 20 | V28: 아페이론102 | W28: 125 | X28: 125 | Y28: 120 | Z28: 8 | AA28: 2.5 | AB28: 2.5 | AC28: 18 | AD28: 원룸
A29: =IF($C29="","",_xlfn.XLOOKUP(_xlfn.CONCAT($C29,$D29),$V:$V,T:T,"",0)) | B29: =IF($C29="","",_xlfn.XLOOKUP(_xlfn.CONCAT($C29,$D29),$V:$V,U:U,"",0)) | E29: =IF(C29="","",_xlfn.XLOOKUP(C29,$Q$6:$Q$100,$R$6:$R$100,"",0)) | F29: =IF($C29="","",_xlfn.XLOOKUP(_xlfn.CONCAT($C29,$D29),$V:$V,W:W,"",0)) | G29: =IF($C29="","",_xlfn.XLOOKUP(_xlfn.CONCAT($C29,$D29),$V:$V,X:X,"",0)) | H29: =IF($C29="","",_xlfn.XLOOKUP(_xlfn.CONCAT($C29,$D29),$V:$V,Y:Y,"",0)) | I29: =IF($C29="","",_xlfn.XLOOKUP(_xlfn.CONCAT($C29,$D29),$V:$V,Z:Z,"",0)) | J29: =IF($C29="","",_xlfn.XLOOKUP(_xlfn.CONCAT($C29,$D29),$V:$V,AA:AA,"",0)) | K29: =IF($C29="","",_xlfn.XLOOKUP(_xlfn.CONCAT($C29,$D29),$V:$V,AB:AB,"",0)) | L29: =IF($C29="","",_xlfn.XLOOKUP(_xlfn.CONCAT($C29,$D29),$V:$V,AC:AC,"",0)) | M29: {=_xlfn.LET(_xlpm.퇴실일, _xlfn.XLOOKUP(_xlfn.CONCAT(C29,D29),■퇴실정보!$B$4:$B$1000&■퇴실정보!$C$4:$C$1000,■퇴실정보!$E$4:$E$1000,0,0,-1),IF(TODAY()-_xlpm.퇴실일>1000,"",TODAY()-_xlpm.퇴실일))} | N29: {=IF($C29="","",_xlfn.XLOOKUP(_xlfn.CONCAT($C29,$D29),◆관리정보!$B:$B & ◆관리정보!$C:$C,◆관리정보!$J:$J))} | Q29: 신림프리미어 | R29: 3333 | U29: 20 | V29: 아페이론103 | W29: 125 | X29: 125 | Y29: 120 | Z29: 8 | AA29: 2.5 | AB29: 2.5 | AC29: 18 | AD29: 원룸
A30: =IF($C30="","",_xlfn.XLOOKUP(_xlfn.CONCAT($C30,$D30),$V:$V,T:T,"",0)) | B30: =IF($C30="","",_xlfn.XLOOKUP(_xlfn.CONCAT($C30,$D30),$V:$V,U:U,"",0)) | E30: =IF(C30="","",_xlfn.XLOOKUP(C30,$Q$6:$Q$100,$R$6:$R$100,"",0)) | F30: =IF($C30="","",_xlfn.XLOOKUP(_xlfn.CONCAT($C30,$D30),$V:$V,W:W,"",0)) | G30: =IF($C30="","",_xlfn.XLOOKUP(_xlfn.CONCAT($C30,$D30),$V:$V,X:X,"",0)) | H30: =IF($C30="","",_xlfn.XLOOKUP(_xlfn.CONCAT($C30,$D30),$V:$V,Y:Y,"",0)) | I30: =IF($C30="","",_xlfn.XLOOKUP(_xlfn.CONCAT($C30,$D30),$V:$V,Z:Z,"",0)) | J30: =IF($C30="","",_xlfn.XLOOKUP(_xlfn.CONCAT($C30,$D30),$V:$V,AA:AA,"",0)) | K30: =IF($C30="","",_xlfn.XLOOKUP(_xlfn.CONCAT($C30,$D30),$V:$V,AB:AB,"",0)) | L30: =IF($C30="","",_xlfn.XLOOKUP(_xlfn.CONCAT($C30,$D30),$V:$V,AC:AC,"",0)) | M30: {=_xlfn.LET(_xlpm.퇴실일, _xlfn.XLOOKUP(_xlfn.CONCAT(C30,D30),■퇴실정보!$B$4:$B$1000&■퇴실정보!$C$4:$C$1000,■퇴실정보!$E$4:$E$1000,0,0,-1),IF(TODAY()-_xlpm.퇴실일>1000,"",TODAY()-_xlpm.퇴실일))} | N30: {=IF($C30="","",_xlfn.XLOOKUP(_xlfn.CONCAT($C30,$D30),◆관리정보!$B:$B & ◆관리정보!$C:$C,◆관리정보!$J:$J))} | Q30: 어반그레이 | R30: 4150 | U30: 20 | V30: 아페이론104 | W30: 125 | X30: 125 | Y30: 120 | Z30: 8 | AA30: 2.5 | AB30: 2.5 | AC30: 18 | AD30: 원룸
A31: =IF($C31="","",_xlfn.XLOOKUP(_xlfn.CONCAT($C31,$D31),$V:$V,T:T,"",0)) | B31: =IF($C31="","",_xlfn.XLOOKUP(_xlfn.CONCAT($C31,$D31),$V:$V,U:U,"",0)) | E31: =IF(C31="","",_xlfn.XLOOKUP(C31,$Q$6:$Q$100,$R$6:$R$100,"",0)) | F31: =IF($C31="","",_xlfn.XLOOKUP(_xlfn.CONCAT($C31,$D31),$V:$V,W:W,"",0)) | G31: =IF($C31="","",_xlfn.XLOOKUP(_xlfn.CONCAT($C31,$D31),$V:$V,X:X,"",0)) | H31: =IF($C31="","",_xlfn.XLOOKUP(_xlfn.CONCAT($C31,$D31),$V:$V,Y:Y,"",0)) | I31: =IF($C31="","",_xlfn.XLOOKUP(_xlfn.CONCAT($C31,$D31),$V:$V,Z:Z,"",0)) | J31: =IF($C31="","",_xlfn.XLOOKUP(_xlfn.CONCAT($C31,$D31),$V:$V,AA:AA,"",0)) | K31: =IF($C31="","",_xlfn.XLOOKUP(_xlfn.CONCAT($C31,$D31),$V:$V,AB:AB,"",0)) | L31: =IF($C31="","",_xlfn.XLOOKUP(_xlfn.CONCAT($C31,$D31),$V:$V,AC:AC,"",0)) | M31: {=_xlfn.LET(_xlpm.퇴실일, _xlfn.XLOOKUP(_xlfn.CONCAT(C31,D31),■퇴실정보!$B$4:$B$1000&■퇴실정보!$C$4:$C$1000,■퇴실정보!$E$4:$E$1000,0,0,-1),IF(TODAY()-_xlpm.퇴실일>1000,"",TODAY()-_xlpm.퇴실일))} | N31: {=IF($C31="","",_xlfn.XLOOKUP(_xlfn.CONCAT($C31,$D31),◆관리정보!$B:$B & ◆관리정보!$C:$C,◆관리정보!$J:$J))} | Q31: 문화빌딩 | R31: OPEN | U31: 20 | V31: 아페이론105 | W31: 125 | X31: 125 | Y31: 120 | Z31: 8 | AA31: 2.5 | AB31: 2.5 | AC31: 18 | AD31: 원룸
A32: =IF($C32="","",_xlfn.XLOOKUP(_xlfn.CONCAT($C32,$D32),$V:$V,T:T,"",0)) | B32: =IF($C32="","",_xlfn.XLOOKUP(_xlfn.CONCAT($C32,$D32),$V:$V,U:U,"",0)) | E32: =IF(C32="","",_xlfn.XLOOKUP(C32,$Q$6:$Q$100,$R$6:$R$100,"",0)) | F32: =IF($C32="","",_xlfn.XLOOKUP(_xlfn.CONCAT($C32,$D32),$V:$V,W:W,"",0)) | G32: =IF($C32="","",_xlfn.XLOOKUP(_xlfn.CONCAT($C32,$D32),$V:$V,X:X,"",0)) | H32: =IF($C32="","",_xlfn.XLOOKUP(_xlfn.CONCAT($C32,$D32),$V:$V,Y:Y,"",0)) | I32: =IF($C32="","",_xlfn.XLOOKUP(_xlfn.CONCAT($C32,$D32),$V:$V,Z:Z,"",0)) | J32: =IF($C32="","",_xlfn.XLOOKUP(_xlfn.CONCAT($C32,$D32),$V:$V,AA:AA,"",0)) | K32: =IF($C32="","",_xlfn.XLOOKUP(_xlfn.CONCAT($C32,$D32),$V:$V,AB:AB,"",0)) | L32: =IF($C32="","",_xlfn.XLOOKUP(_xlfn.CONCAT($C32,$D32),$V:$V,AC:AC,"",0)) | M32: {=_xlfn.LET(_xlpm.퇴실일, _xlfn.XLOOKUP(_xlfn.CONCAT(C32,D32),■퇴실정보!$B$4:$B$1000&■퇴실정보!$C$4:$C$1000,■퇴실정보!$E$4:$E$1000,0,0,-1),IF(TODAY()-_xlpm.퇴실일>1000,"",TODAY()-_xlpm.퇴실일))} | N32: {=IF($C32="","",_xlfn.XLOOKUP(_xlfn.CONCAT($C32,$D32),◆관리정보!$B:$B & ◆관리정보!$C:$C,◆관리정보!$J:$J))} | Q32: 집현전빌딩 | R32: OPEN | U32: 20 | V32: 아페이론201 | W32: 125 | X32: 125 | Y32: 120 | Z32: 8 | AA32: 2.5 | AB32: 2.5 | AC32: 18 | AD32: 원룸
